5:return {{["x"] = 0, ["y"] = 5, ["z"] = 5, ["name"] = "default:wood"}, {["x"] = 0, ["y"] = 5, ["z"] = 6, ["name"] = "default:wood"}, {["x"] = 0, ["y"] = 5, ["z"] = 7, ["name"] = "default:wood"}, {["x"] = 0, ["y"] = 5, ["z"] = 8, ["name"] = "default:wood"}, {["x"] = 0, ["y"] = 5, ["z"] = 9, ["name"] = "default:wood"}, {["x"] = 0, ["y"] = 5, ["z"] = 10, ["name"] = "default:wood"}, {["x"] = 0, ["y"] = 6, ["z"] = 5, ["name"] = "default:wood"}, {["x"] = 0, ["y"] = 6, ["z"] = 6, ["name"] = "default:wood"}, {["x"] = 0, ["y"] = 6, ["z"] = 7, ["name"] = "default:wood"}, {["x"] = 0, ["y"] = 6, ["z"] = 8, ["name"] = "default:wood"}, {["x"] = 0, ["y"] = 6, ["z"] = 9, ["name"] = "default:wood"}, {["x"] = 0, ["y"] = 6, ["z"] = 10, ["name"] = "default:wood"}, {["x"] = 0, ["y"] = 7, ["z"] = 5, ["name"] = "default:wood"}, {["x"] = 0, ["y"] = 7, ["z"] = 6, ["name"] = "default:wood"}, {["x"] = 0, ["y"] = 7, ["z"] = 7, ["name"] = "default:wood"}, {["x"] = 0, ["y"] = 7, ["z"] = 8, ["name"] = "default:wood"}, {["x"] = 0, ["y"] = 7, ["z"] = 9, ["name"] = "default:wood"}, {["x"] = 0, ["y"] = 7, ["z"] = 10, ["name"] = "default:wood"}, {["x"] = 0, ["y"] = 8, ["z"] = 5, ["name"] = "default:wood"}, {["x"] = 0, ["y"] = 8, ["z"] = 6, ["name"] = "default:wood"}, {["x"] = 0, ["y"] = 8, ["z"] = 7, ["name"] = "default:wood"}, {["x"] = 0, ["y"] = 8, ["z"] = 8, ["name"] = "default:wood"}, {["x"] = 0, ["y"] = 8, ["z"] = 9, ["name"] = "default:wood"}, {["x"] = 0, ["y"] = 8, ["z"] = 10, ["name"] = "default:wood"}, {["x"] = 0, ["y"] = 9, ["z"] = 5, ["name"] = "default:wood"}, {["x"] = 0, ["y"] = 9, ["z"] = 6, ["name"] = "default:wood"}, {["x"] = 0, ["y"] = 9, ["z"] = 7, ["name"] = "default:wood"}, {["x"] = 0, ["y"] = 9, ["z"] = 8, ["name"] = "default:wood"}, {["x"] = 0, ["y"] = 9, ["z"] = 9, ["name"] = "default:wood"}, {["x"] = 0, ["y"] = 9, ["z"] = 10, ["name"] = "default:wood"}, {["x"] = 0, ["y"] = 10, ["z"] = 5, ["name"] = "default:wood"}, {["x"] = 0, ["y"] = 10, ["z"] = 6, ["name"] = "default:wood"}, {["x"] = 0, ["y"] = 10, ["z"] = 7, ["name"] = "default:wood"}, {["x"] = 0, ["y"] = 10, ["z"] = 8, ["name"] = "default:wood"}, {["x"] = 0, ["y"] = 10, ["z"] = 9, ["name"] = "default:wood"}, {["x"] = 0, ["y"] = 10, ["z"] = 10, ["name"] = "default:wood"}, {["x"] = 1, ["y"] = 2, ["z"] = 1, ["name"] = "default:steelblock"}, {["x"] = 1, ["y"] = 2, ["param1"] = 15, ["z"] = 2, ["name"] = "default:steelblock"}, {["x"] = 1, ["y"] = 2, ["param1"] = 15, ["z"] = 3, ["name"] = "default:steelblock"}, {["x"] = 1, ["y"] = 2, ["param1"] = 15, ["z"] = 4, ["name"] = "default:steelblock"}, {["x"] = 1, ["y"] = 2, ["param1"] = 15, ["z"] = 5, ["name"] = "default:steelblock"}, {["x"] = 1, ["y"] = 2, ["param1"] = 15, ["z"] = 6, ["name"] = "default:steelblock"}, {["x"] = 1, ["y"] = 2, ["param1"] = 15, ["z"] = 7, ["name"] = "default:steelblock"}, {["x"] = 1, ["y"] = 2, ["param1"] = 15, ["z"] = 8, ["name"] = "default:steelblock"}, {["x"] = 1, ["y"] = 2, ["param1"] = 15, ["z"] = 9, ["name"] = "default:steelblock"}, {["x"] = 1, ["y"] = 2, ["param1"] = 15, ["z"] = 10, ["name"] = "default:steelblock"}, {["x"] = 1, ["y"] = 2, ["param1"] = 15, ["z"] = 11, ["name"] = "default:steelblock"}, {["x"] = 1, ["y"] = 2, ["param1"] = 15, ["z"] = 12, ["name"] = "default:steelblock"}, {["x"] = 1, ["y"] = 2, ["param1"] = 15, ["z"] = 13, ["name"] = "default:steelblock"}, {["x"] = 1, ["y"] = 2, ["param1"] = 15, ["z"] = 14, ["name"] = "default:steelblock"}, {["x"] = 1, ["y"] = 3, ["z"] = 1, ["name"] = "default:steelblock"}, {["x"] = 1, ["y"] = 3, ["param1"] = 15, ["z"] = 2, ["name"] = "default:steelblock"}, {["x"] = 1, ["y"] = 3, ["param1"] = 15, ["z"] = 3, ["name"] = "default:steelblock"}, {["x"] = 1, ["y"] = 3, ["param1"] = 15, ["z"] = 4, ["name"] = "default:steelblock"}, {["x"] = 1, ["y"] = 3, ["param1"] = 15, ["z"] = 5, ["name"] = "default:steelblock"}, {["x"] = 1, ["y"] = 3, ["param1"] = 15, ["z"] = 6, ["name"] = "default:steelblock"}, {["x"] = 1, ["y"] = 3, ["param1"] = 15, ["z"] = 7, ["name"] = "default:steelblock"}, {["x"] = 1, ["y"] = 3, ["param1"] = 15, ["z"] = 8, ["name"] = "default:steelblock"}, {["x"] = 1, ["y"] = 3, ["param1"] = 15, ["z"] = 9, ["name"] = "default:steelblock"}, {["x"] = 1, ["y"] = 3, ["param1"] = 15, ["z"] = 10, ["name"] = "default:steelblock"}, {["x"] = 1, ["y"] = 3, ["param1"] = 15, ["z"] = 11, ["name"] = "default:steelblock"}, {["x"] = 1, ["y"] = 3, ["param1"] = 15, ["z"] = 12, ["name"] = "default:steelblock"}, {["x"] = 1, ["y"] = 3, ["param1"] = 15, ["z"] = 13, ["name"] = "default:steelblock"}, {["x"] = 1, ["y"] = 3, ["param1"] = 15, ["z"] = 14, ["name"] = "default:steelblock"}, {["x"] = 1, ["y"] = 4, ["z"] = 1, ["name"] = "default:steelblock"}, {["x"] = 1, ["y"] = 4, ["param1"] = 15, ["z"] = 2, ["name"] = "default:steelblock"}, {["x"] = 1, ["y"] = 4, ["param1"] = 15, ["z"] = 3, ["name"] = "default:steelblock"}, {["x"] = 1, ["y"] = 4, ["param1"] = 15, ["z"] = 4, ["name"] = "default:steelblock"}, {["x"] = 1, ["y"] = 4, ["param1"] = 15, ["z"] = 5, ["name"] = "default:steelblock"}, {["x"] = 1, ["y"] = 4, ["param1"] = 15, ["z"] = 6, ["name"] = "default:steelblock"}, {["x"] = 1, ["y"] = 4, ["param1"] = 15, ["z"] = 7, ["name"] = "default:steelblock"}, {["x"] = 1, ["y"] = 4, ["param1"] = 15, ["z"] = 8, ["name"] = "default:steelblock"}, {["x"] = 1, ["y"] = 4, ["param1"] = 15, ["z"] = 9, ["name"] = "default:steelblock"}, {["x"] = 1, ["y"] = 4, ["param1"] = 15, ["z"] = 10, ["name"] = "default:steelblock"}, {["x"] = 1, ["y"] = 4, ["param1"] = 15, ["z"] = 11, ["name"] = "default:steelblock"}, {["x"] = 1, ["y"] = 4, ["param1"] = 15, ["z"] = 12, ["name"] = "default:steelblock"}, {["x"] = 1, ["y"] = 4, ["param1"] = 15, ["z"] = 13, ["name"] = "default:steelblock"}, {["x"] = 1, ["y"] = 4, ["param1"] = 15, ["z"] = 14, ["name"] = "default:steelblock"}, {["x"] = 1, ["y"] = 5, ["z"] = 1, ["name"] = "default:steelblock"}, {["x"] = 1, ["y"] = 5, ["param1"] = 15, ["z"] = 2, ["name"] = "default:steelblock"}, {["x"] = 1, ["y"] = 5, ["param1"] = 15, ["z"] = 3, ["name"] = "default:steelblock"}, {["x"] = 1, ["y"] = 5, ["param1"] = 15, ["z"] = 4, ["name"] = "default:steelblock"}, {["x"] = 1, ["y"] = 5, ["param1"] = 15, ["z"] = 5, ["name"] = "default:steelblock"}, {["x"] = 1, ["y"] = 5, ["param1"] = 15, ["z"] = 6, ["name"] = "default:steelblock"}, {["x"] = 1, ["y"] = 5, ["param1"] = 15, ["z"] = 7, ["name"] = "default:steelblock"}, {["x"] = 1, ["y"] = 5, ["param1"] = 15, ["z"] = 8, ["name"] = "default:steelblock"}, {["x"] = 1, ["y"] = 5, ["param1"] = 15, ["z"] = 9, ["name"] = "default:steelblock"}, {["x"] = 1, ["y"] = 5, ["param1"] = 15, ["z"] = 10, ["name"] = "default:steelblock"}, {["x"] = 1, ["y"] = 5, ["param1"] = 15, ["z"] = 11, ["name"] = "default:steelblock"}, {["x"] = 1, ["y"] = 5, ["param1"] = 15, ["z"] = 12, ["name"] = "default:steelblock"}, {["x"] = 1, ["y"] = 5, ["param1"] = 15, ["z"] = 13, ["name"] = "default:steelblock"}, {["x"] = 1, ["y"] = 5, ["param1"] = 15, ["z"] = 14, ["name"] = "default:steelblock"}, {["x"] = 1, ["y"] = 6, ["z"] = 1, ["name"] = "default:steelblock"}, {["x"] = 1, ["y"] = 6, ["param1"] = 15, ["z"] = 2, ["name"] = "default:steelblock"}, {["x"] = 1, ["y"] = 6, ["param1"] = 15, ["z"] = 3, ["name"] = "default:steelblock"}, {["x"] = 1, ["y"] = 6, ["param1"] = 15, ["z"] = 4, ["name"] = "default:steelblock"}, {["x"] = 1, ["y"] = 6, ["param1"] = 15, ["z"] = 5, ["name"] = "default:steelblock"}, {["x"] = 1, ["y"] = 6, ["param1"] = 15, ["z"] = 6, ["name"] = "default:steelblock"}, {["x"] = 1, ["y"] = 6, ["z"] = 7, ["name"] = "default:steelblock"}, {["x"] = 1, ["y"] = 6, ["param1"] = 15, ["z"] = 8, ["name"] = "default:steelblock"}, {["x"] = 1, ["y"] = 6, ["param1"] = 15, ["z"] = 9, ["name"] = "default:steelblock"}, {["x"] = 1, ["y"] = 6, ["param1"] = 15, ["z"] = 10, ["name"] = "default:steelblock"}, {["x"] = 1, ["y"] = 6, ["param1"] = 15, ["z"] = 11, ["name"] = "default:steelblock"}, {["x"] = 1, ["y"] = 6, ["param1"] = 15, ["z"] = 12, ["name"] = "default:steelblock"}, {["x"] = 1, ["y"] = 6, ["param1"] = 15, ["z"] = 13, ["name"] = "default:steelblock"}, {["x"] = 1, ["y"] = 6, ["param1"] = 15, ["z"] = 14, ["name"] = "default:steelblock"}, {["x"] = 1, ["y"] = 7, ["z"] = 1, ["name"] = "default:steelblock"}, {["x"] = 1, ["y"] = 7, ["param1"] = 15, ["z"] = 2, ["name"] = "default:steelblock"}, {["x"] = 1, ["y"] = 7, ["param1"] = 15, ["z"] = 3, ["name"] = "default:steelblock"}, {["x"] = 1, ["y"] = 7, ["param1"] = 15, ["z"] = 4, ["name"] = "default:steelblock"}, {["x"] = 1, ["y"] = 7, ["param1"] = 15, ["z"] = 5, ["name"] = "default:steelblock"}, {["x"] = 1, ["y"] = 7, ["param1"] = 15, ["z"] = 6, ["name"] = "default:steelblock"}, {["x"] = 1, ["y"] = 7, ["param1"] = 15, ["z"] = 7, ["name"] = "default:steelblock"}, {["x"] = 1, ["y"] = 7, ["param1"] = 15, ["z"] = 8, ["name"] = "default:steelblock"}, {["x"] = 1, ["y"] = 7, ["param1"] = 15, ["z"] = 9, ["name"] = "default:steelblock"}, {["x"] = 1, ["y"] = 7, ["param1"] = 15, ["z"] = 10, ["name"] = "default:steelblock"}, {["x"] = 1, ["y"] = 7, ["param1"] = 15, ["z"] = 11, ["name"] = "default:steelblock"}, {["x"] = 1, ["y"] = 7, ["param1"] = 15, ["z"] = 12, ["name"] = "default:steelblock"}, {["x"] = 1, ["y"] = 7, ["param1"] = 15, ["z"] = 13, ["name"] = "default:steelblock"}, {["x"] = 1, ["y"] = 7, ["param1"] = 15, ["z"] = 14, ["name"] = "default:steelblock"}, {["x"] = 1, ["y"] = 8, ["param1"] = 15, ["z"] = 1, ["name"] = "default:steelblock"}, {["x"] = 1, ["y"] = 8, ["param1"] = 15, ["z"] = 2, ["name"] = "default:steelblock"}, {["x"] = 1, ["y"] = 8, ["param1"] = 15, ["z"] = 3, ["name"] = "default:steelblock"}, {["x"] = 1, ["y"] = 8, ["param1"] = 15, ["z"] = 4, ["name"] = "default:steelblock"}, {["x"] = 1, ["y"] = 8, ["param1"] = 15, ["z"] = 5, ["name"] = "default:steelblock"}, {["x"] = 1, ["y"] = 8, ["param1"] = 15, ["z"] = 6, ["name"] = "default:steelblock"}, {["x"] = 1, ["y"] = 8, ["param1"] = 15, ["z"] = 7, ["name"] = "default:steelblock"}, {["x"] = 1, ["y"] = 8, ["param1"] = 15, ["z"] = 8, ["name"] = "default:steelblock"}, {["x"] = 1, ["y"] = 8, ["param1"] = 15, ["z"] = 9, ["name"] = "default:steelblock"}, {["x"] = 1, ["y"] = 8, ["param1"] = 15, ["z"] = 10, ["name"] = "default:steelblock"}, {["x"] = 1, ["y"] = 8, ["param1"] = 15, ["z"] = 11, ["name"] = "default:steelblock"}, {["x"] = 1, ["y"] = 8, ["param1"] = 15, ["z"] = 12, ["name"] = "default:steelblock"}, {["x"] = 1, ["y"] = 8, ["param1"] = 15, ["z"] = 13, ["name"] = "default:steelblock"}, {["x"] = 1, ["y"] = 8, ["param1"] = 15, ["z"] = 14, ["name"] = "default:steelblock"}, {["x"] = 1, ["y"] = 9, ["param1"] = 15, ["z"] = 1, ["name"] = "default:steelblock"}, {["x"] = 1, ["y"] = 9, ["param1"] = 15, ["z"] = 2, ["name"] = "default:steelblock"}, {["x"] = 1, ["y"] = 9, ["param1"] = 15, ["z"] = 3, ["name"] = "default:steelblock"}, {["x"] = 1, ["y"] = 9, ["param1"] = 15, ["z"] = 4, ["name"] = "default:steelblock"}, {["x"] = 1, ["y"] = 9, ["param1"] = 15, ["z"] = 5, ["name"] = "default:steelblock"}, {["x"] = 1, ["y"] = 9, ["param1"] = 15, ["z"] = 6, ["name"] = "default:steelblock"}, {["x"] = 1, ["y"] = 9, ["param1"] = 15, ["z"] = 7, ["name"] = "default:steelblock"}, {["x"] = 1, ["y"] = 9, ["param1"] = 15, ["z"] = 8, ["name"] = "default:steelblock"}, {["x"] = 1, ["y"] = 9, ["param1"] = 15, ["z"] = 9, ["name"] = "default:steelblock"}, {["x"] = 1, ["y"] = 9, ["param1"] = 15, ["z"] = 10, ["name"] = "default:steelblock"}, {["x"] = 1, ["y"] = 9, ["param1"] = 15, ["z"] = 11, ["name"] = "default:steelblock"}, {["x"] = 1, ["y"] = 9, ["param1"] = 15, ["z"] = 12, ["name"] = "default:steelblock"}, {["x"] = 1, ["y"] = 9, ["param1"] = 15, ["z"] = 13, ["name"] = "default:steelblock"}, {["x"] = 1, ["y"] = 9, ["param1"] = 15, ["z"] = 14, ["name"] = "default:steelblock"}, {["x"] = 1, ["y"] = 10, ["param1"] = 15, ["z"] = 1, ["name"] = "default:steelblock"}, {["x"] = 1, ["y"] = 10, ["param1"] = 15, ["z"] = 2, ["name"] = "default:steelblock"}, {["x"] = 1, ["y"] = 10, ["param1"] = 15, ["z"] = 3, ["name"] = "default:steelblock"}, {["x"] = 1, ["y"] = 10, ["param1"] = 15, ["z"] = 4, ["name"] = "default:steelblock"}, {["x"] = 1, ["y"] = 10, ["param1"] = 15, ["z"] = 5, ["name"] = "default:steelblock"}, {["x"] = 1, ["y"] = 10, ["param1"] = 15, ["z"] = 6, ["name"] = "default:steelblock"}, {["x"] = 1, ["y"] = 10, ["param1"] = 15, ["z"] = 7, ["name"] = "default:steelblock"}, {["x"] = 1, ["y"] = 10, ["param1"] = 15, ["z"] = 8, ["name"] = "default:steelblock"}, {["x"] = 1, ["y"] = 10, ["param1"] = 15, ["z"] = 9, ["name"] = "default:steelblock"}, {["x"] = 1, ["y"] = 10, ["param1"] = 15, ["z"] = 10, ["name"] = "default:steelblock"}, {["x"] = 1, ["y"] = 10, ["param1"] = 15, ["z"] = 11, ["name"] = "default:steelblock"}, {["x"] = 1, ["y"] = 10, ["param1"] = 15, ["z"] = 12, ["name"] = "default:steelblock"}, {["x"] = 1, ["y"] = 10, ["param1"] = 15, ["z"] = 13, ["name"] = "default:steelblock"}, {["x"] = 1, ["y"] = 10, ["param1"] = 15, ["z"] = 14, ["name"] = "default:steelblock"}, {["x"] = 1, ["y"] = 11, ["param1"] = 15, ["z"] = 1, ["name"] = "default:steelblock"}, {["x"] = 1, ["y"] = 11, ["param1"] = 15, ["z"] = 2, ["name"] = "default:steelblock"}, {["x"] = 1, ["y"] = 11, ["param1"] = 15, ["z"] = 3, ["name"] = "default:steelblock"}, {["x"] = 1, ["y"] = 11, ["param1"] = 15, ["z"] = 4, ["name"] = "default:steelblock"}, {["x"] = 1, ["y"] = 11, ["param1"] = 15, ["z"] = 5, ["name"] = "default:steelblock"}, {["x"] = 1, ["y"] = 11, ["param1"] = 15, ["z"] = 6, ["name"] = "default:steelblock"}, {["x"] = 1, ["y"] = 11, ["param1"] = 15, ["z"] = 7, ["name"] = "default:steelblock"}, {["x"] = 1, ["y"] = 11, ["param1"] = 15, ["z"] = 8, ["name"] = "default:steelblock"}, {["x"] = 1, ["y"] = 11, ["param1"] = 15, ["z"] = 9, ["name"] = "default:steelblock"}, {["x"] = 1, ["y"] = 11, ["param1"] = 15, ["z"] = 10, ["name"] = "default:steelblock"}, {["x"] = 1, ["y"] = 11, ["param1"] = 15, ["z"] = 11, ["name"] = "default:steelblock"}, {["x"] = 1, ["y"] = 11, ["param1"] = 15, ["z"] = 12, ["name"] = "default:steelblock"}, {["x"] = 1, ["y"] = 11, ["param1"] = 15, ["z"] = 13, ["name"] = "default:steelblock"}, {["x"] = 1, ["y"] = 11, ["param1"] = 15, ["z"] = 14, ["name"] = "default:steelblock"}, {["x"] = 1, ["y"] = 14, ["z"] = 1, ["name"] = "wool:black"}, {["x"] = 1, ["y"] = 14, ["z"] = 2, ["name"] = "wool:black"}, {["x"] = 1, ["y"] = 14, ["z"] = 3, ["name"] = "wool:black"}, {["x"] = 1, ["y"] = 14, ["z"] = 4, ["name"] = "wool:black"}, {["x"] = 1, ["y"] = 14, ["z"] = 5, ["name"] = "wool:black"}, {["x"] = 1, ["y"] = 14, ["z"] = 6, ["name"] = "wool:black"}, {["x"] = 1, ["y"] = 14, ["z"] = 7, ["name"] = "wool:black"}, {["x"] = 1, ["y"] = 14, ["z"] = 8, ["name"] = "wool:black"}, {["x"] = 1, ["y"] = 14, ["z"] = 9, ["name"] = "wool:black"}, {["x"] = 1, ["y"] = 14, ["z"] = 10, ["name"] = "wool:black"}, {["x"] = 1, ["y"] = 14, ["z"] = 11, ["name"] = "wool:black"}, {["x"] = 1, ["y"] = 14, ["z"] = 12, ["name"] = "wool:black"}, {["x"] = 1, ["y"] = 14, ["z"] = 13, ["name"] = "wool:black"}, {["x"] = 1, ["y"] = 14, ["z"] = 14, ["name"] = "wool:black"}, {["x"] = 1, ["y"] = 15, ["z"] = 1, ["name"] = "wool:black"}, {["x"] = 1, ["y"] = 15, ["z"] = 2, ["name"] = "wool:black"}, {["x"] = 1, ["y"] = 15, ["z"] = 3, ["name"] = "wool:black"}, {["x"] = 1, ["y"] = 15, ["z"] = 4, ["name"] = "wool:black"}, {["x"] = 1, ["y"] = 15, ["z"] = 5, ["name"] = "wool:black"}, {["x"] = 1, ["y"] = 15, ["z"] = 6, ["name"] = "wool:black"}, {["x"] = 1, ["y"] = 15, ["z"] = 7, ["name"] = "wool:black"}, {["x"] = 1, ["y"] = 15, ["z"] = 8, ["name"] = "wool:black"}, {["x"] = 1, ["y"] = 15, ["z"] = 9, ["name"] = "wool:black"}, {["x"] = 1, ["y"] = 15, ["z"] = 10, ["name"] = "wool:black"}, {["x"] = 1, ["y"] = 15, ["z"] = 11, ["name"] = "wool:black"}, {["x"] = 1, ["y"] = 15, ["z"] = 12, ["name"] = "wool:black"}, {["x"] = 1, ["y"] = 15, ["z"] = 13, ["name"] = "wool:black"}, {["x"] = 1, ["y"] = 15, ["z"] = 14, ["name"] = "wool:black"}, {["x"] = 2, ["y"] = 0, ["param1"] = 15, ["z"] = 2, ["name"] = "wool:black"}, {["x"] = 2, ["y"] = 0, ["param1"] = 15, ["z"] = 3, ["name"] = "wool:black"}, {["x"] = 2, ["y"] = 0, ["param1"] = 15, ["z"] = 4, ["name"] = "wool:black"}, {["x"] = 2, ["y"] = 0, ["param1"] = 15, ["z"] = 5, ["name"] = "wool:black"}, {["x"] = 2, ["y"] = 0, ["param1"] = 15, ["z"] = 6, ["name"] = "wool:black"}, {["x"] = 2, ["y"] = 0, ["param1"] = 15, ["z"] = 7, ["name"] = "wool:black"}, {["x"] = 2, ["y"] = 0, ["param1"] = 15, ["z"] = 8, ["name"] = "wool:black"}, {["x"] = 2, ["y"] = 0, ["param1"] = 15, ["z"] = 9, ["name"] = "wool:black"}, {["x"] = 2, ["y"] = 0, ["param1"] = 15, ["z"] = 10, ["name"] = "wool:black"}, {["x"] = 2, ["y"] = 0, ["param1"] = 14, ["z"] = 11, ["name"] = "wool:black"}, {["x"] = 2, ["y"] = 0, ["param1"] = 14, ["z"] = 12, ["name"] = "wool:black"}, {["x"] = 2, ["y"] = 0, ["param1"] = 14, ["z"] = 13, ["name"] = "wool:black"}, {["x"] = 2, ["y"] = 1, ["param1"] = 15, ["z"] = 2, ["name"] = "wool:black"}, {["x"] = 2, ["y"] = 1, ["param1"] = 15, ["z"] = 3, ["name"] = "wool:black"}, {["x"] = 2, ["y"] = 1, ["param1"] = 15, ["z"] = 4, ["name"] = "wool:black"}, {["x"] = 2, ["y"] = 1, ["param1"] = 15, ["z"] = 5, ["name"] = "wool:black"}, {["x"] = 2, ["y"] = 1, ["param1"] = 15, ["z"] = 6, ["name"] = "wool:black"}, {["x"] = 2, ["y"] = 1, ["param1"] = 15, ["z"] = 7, ["name"] = "wool:black"}, {["x"] = 2, ["y"] = 1, ["param1"] = 15, ["z"] = 8, ["name"] = "wool:black"}, {["x"] = 2, ["y"] = 1, ["param1"] = 15, ["z"] = 9, ["name"] = "wool:black"}, {["x"] = 2, ["y"] = 1, ["param1"] = 15, ["z"] = 10, ["name"] = "wool:black"}, {["x"] = 2, ["y"] = 1, ["param1"] = 15, ["z"] = 11, ["name"] = "wool:black"}, {["x"] = 2, ["y"] = 1, ["param1"] = 15, ["z"] = 12, ["name"] = "wool:black"}, {["x"] = 2, ["y"] = 1, ["param1"] = 15, ["z"] = 13, ["name"] = "wool:black"}, {["x"] = 2, ["y"] = 2, ["param1"] = 15, ["z"] = 1, ["name"] = "default:steelblock"}, {["x"] = 2, ["y"] = 2, ["param1"] = 15, ["z"] = 2, ["name"] = "wool:black"}, {["x"] = 2, ["y"] = 2, ["param1"] = 15, ["z"] = 3, ["name"] = "wool:black"}, {["x"] = 2, ["y"] = 2, ["param1"] = 15, ["z"] = 4, ["name"] = "wool:black"}, {["x"] = 2, ["y"] = 2, ["param1"] = 15, ["z"] = 5, ["name"] = "wool:black"}, {["x"] = 2, ["y"] = 2, ["param1"] = 15, ["z"] = 6, ["name"] = "wool:black"}, {["x"] = 2, ["y"] = 2, ["param1"] = 15, ["z"] = 7, ["name"] = "wool:black"}, {["x"] = 2, ["y"] = 2, ["param1"] = 15, ["z"] = 8, ["name"] = "wool:black"}, {["x"] = 2, ["y"] = 2, ["param1"] = 15, ["z"] = 9, ["name"] = "wool:black"}, {["x"] = 2, ["y"] = 2, ["param1"] = 15, ["z"] = 10, ["name"] = "wool:black"}, {["x"] = 2, ["y"] = 2, ["param1"] = 15, ["z"] = 11, ["name"] = "wool:black"}, {["x"] = 2, ["y"] = 2, ["param1"] = 15, ["z"] = 12, ["name"] = "wool:black"}, {["x"] = 2, ["y"] = 2, ["param1"] = 15, ["z"] = 13, ["name"] = "wool:black"}, {["x"] = 2, ["y"] = 2, ["param1"] = 15, ["z"] = 14, ["name"] = "default:steelblock"}, {["x"] = 2, ["y"] = 3, ["param1"] = 15, ["z"] = 1, ["name"] = "default:steelblock"}, {["x"] = 2, ["y"] = 3, ["param1"] = 15, ["z"] = 2, ["name"] = "wool:black"}, {["x"] = 2, ["y"] = 3, ["param1"] = 15, ["z"] = 3, ["name"] = "wool:black"}, {["x"] = 2, ["y"] = 3, ["param1"] = 15, ["z"] = 4, ["name"] = "wool:black"}, {["x"] = 2, ["y"] = 3, ["param1"] = 15, ["z"] = 5, ["name"] = "wool:black"}, {["x"] = 2, ["y"] = 3, ["param1"] = 15, ["z"] = 6, ["name"] = "wool:black"}, {["x"] = 2, ["y"] = 3, ["param1"] = 15, ["z"] = 7, ["name"] = "wool:black"}, {["x"] = 2, ["y"] = 3, ["param1"] = 15, ["z"] = 8, ["name"] = "wool:black"}, {["x"] = 2, ["y"] = 3, ["param1"] = 15, ["z"] = 9, ["name"] = "wool:black"}, {["x"] = 2, ["y"] = 3, ["param1"] = 15, ["z"] = 10, ["name"] = "wool:black"}, {["x"] = 2, ["y"] = 3, ["param1"] = 15, ["z"] = 11, ["name"] = "wool:black"}, {["x"] = 2, ["y"] = 3, ["param1"] = 15, ["z"] = 12, ["name"] = "wool:black"}, {["x"] = 2, ["y"] = 3, ["param1"] = 15, ["z"] = 13, ["name"] = "wool:black"}, {["x"] = 2, ["y"] = 3, ["param1"] = 15, ["z"] = 14, ["name"] = "default:steelblock"}, {["x"] = 2, ["y"] = 4, ["param1"] = 15, ["z"] = 1, ["name"] = "default:steelblock"}, {["x"] = 2, ["y"] = 4, ["param1"] = 15, ["z"] = 2, ["name"] = "wool:black"}, {["x"] = 2, ["y"] = 4, ["param1"] = 15, ["z"] = 3, ["name"] = "wool:black"}, {["x"] = 2, ["y"] = 4, ["param1"] = 15, ["z"] = 4, ["name"] = "wool:black"}, {["x"] = 2, ["y"] = 4, ["param1"] = 15, ["z"] = 5, ["name"] = "wool:black"}, {["x"] = 2, ["y"] = 4, ["param1"] = 15, ["z"] = 6, ["name"] = "wool:black"}, {["x"] = 2, ["y"] = 4, ["param1"] = 15, ["z"] = 7, ["name"] = "wool:black"}, {["x"] = 2, ["y"] = 4, ["param1"] = 15, ["z"] = 8, ["name"] = "wool:black"}, {["x"] = 2, ["y"] = 4, ["param1"] = 15, ["z"] = 9, ["name"] = "wool:black"}, {["x"] = 2, ["y"] = 4, ["param1"] = 15, ["z"] = 10, ["name"] = "wool:black"}, {["x"] = 2, ["y"] = 4, ["param1"] = 15, ["z"] = 11, ["name"] = "wool:black"}, {["x"] = 2, ["y"] = 4, ["param1"] = 15, ["z"] = 12, ["name"] = "wool:black"}, {["x"] = 2, ["y"] = 4, ["param1"] = 15, ["z"] = 13, ["name"] = "wool:black"}, {["x"] = 2, ["y"] = 4, ["param1"] = 15, ["z"] = 14, ["name"] = "default:steelblock"}, {["x"] = 2, ["y"] = 5, ["param1"] = 15, ["z"] = 1, ["name"] = "default:steelblock"}, {["x"] = 2, ["y"] = 5, ["param1"] = 15, ["z"] = 2, ["name"] = "wool:black"}, {["x"] = 2, ["y"] = 5, ["param1"] = 15, ["z"] = 3, ["name"] = "wool:black"}, {["x"] = 2, ["y"] = 5, ["param1"] = 15, ["z"] = 4, ["name"] = "wool:black"}, {["x"] = 2, ["y"] = 5, ["param1"] = 15, ["z"] = 5, ["name"] = "wool:black"}, {["x"] = 2, ["y"] = 5, ["param1"] = 15, ["z"] = 6, ["name"] = "wool:black"}, {["x"] = 2, ["y"] = 5, ["param1"] = 15, ["z"] = 7, ["name"] = "wool:black"}, {["x"] = 2, ["y"] = 5, ["param1"] = 15, ["z"] = 8, ["name"] = "wool:black"}, {["x"] = 2, ["y"] = 5, ["param1"] = 15, ["z"] = 9, ["name"] = "wool:black"}, {["x"] = 2, ["y"] = 5, ["param1"] = 15, ["z"] = 10, ["name"] = "wool:black"}, {["x"] = 2, ["y"] = 5, ["param1"] = 15, ["z"] = 11, ["name"] = "wool:black"}, {["x"] = 2, ["y"] = 5, ["param1"] = 15, ["z"] = 12, ["name"] = "wool:black"}, {["x"] = 2, ["y"] = 5, ["param1"] = 15, ["z"] = 13, ["name"] = "wool:black"}, {["x"] = 2, ["y"] = 5, ["param1"] = 15, ["z"] = 14, ["name"] = "default:steelblock"}, {["x"] = 2, ["y"] = 6, ["param1"] = 15, ["z"] = 1, ["name"] = "default:steelblock"}, {["x"] = 2, ["y"] = 6, ["param1"] = 15, ["z"] = 2, ["name"] = "wool:black"}, {["x"] = 2, ["y"] = 6, ["param1"] = 15, ["z"] = 3, ["name"] = "wool:black"}, {["x"] = 2, ["y"] = 6, ["param1"] = 15, ["z"] = 4, ["name"] = "wool:black"}, {["x"] = 2, ["y"] = 6, ["param1"] = 15, ["z"] = 5, ["name"] = "wool:black"}, {["x"] = 2, ["y"] = 6, ["param1"] = 15, ["z"] = 6, ["name"] = "wool:black"}, {["x"] = 2, ["y"] = 6, ["param1"] = 15, ["z"] = 7, ["name"] = "wool:black"}, {["x"] = 2, ["y"] = 6, ["param1"] = 15, ["z"] = 8, ["name"] = "wool:black"}, {["x"] = 2, ["y"] = 6, ["param1"] = 15, ["z"] = 9, ["name"] = "wool:black"}, {["x"] = 2, ["y"] = 6, ["param1"] = 15, ["z"] = 10, ["name"] = "wool:black"}, {["x"] = 2, ["y"] = 6, ["param1"] = 15, ["z"] = 11, ["name"] = "wool:black"}, {["x"] = 2, ["y"] = 6, ["param1"] = 15, ["z"] = 12, ["name"] = "wool:black"}, {["x"] = 2, ["y"] = 6, ["param1"] = 15, ["z"] = 13, ["name"] = "wool:black"}, {["x"] = 2, ["y"] = 6, ["param1"] = 15, ["z"] = 14, ["name"] = "default:steelblock"}, {["x"] = 2, ["y"] = 7, ["param1"] = 15, ["z"] = 1, ["name"] = "default:steelblock"}, {["x"] = 2, ["y"] = 7, ["param1"] = 15, ["z"] = 2, ["name"] = "wool:black"}, {["x"] = 2, ["y"] = 7, ["param1"] = 15, ["z"] = 3, ["name"] = "wool:black"}, {["x"] = 2, ["y"] = 7, ["param1"] = 15, ["z"] = 4, ["name"] = "wool:black"}, {["x"] = 2, ["y"] = 7, ["param1"] = 15, ["z"] = 5, ["name"] = "wool:black"}, {["x"] = 2, ["y"] = 7, ["param1"] = 15, ["z"] = 6, ["name"] = "wool:black"}, {["x"] = 2, ["y"] = 7, ["param1"] = 15, ["z"] = 7, ["name"] = "wool:black"}, {["x"] = 2, ["y"] = 7, ["param1"] = 15, ["z"] = 8, ["name"] = "wool:black"}, {["x"] = 2, ["y"] = 7, ["param1"] = 15, ["z"] = 9, ["name"] = "wool:black"}, {["x"] = 2, ["y"] = 7, ["param1"] = 15, ["z"] = 10, ["name"] = "wool:black"}, {["x"] = 2, ["y"] = 7, ["param1"] = 15, ["z"] = 11, ["name"] = "wool:black"}, {["x"] = 2, ["y"] = 7, ["param1"] = 15, ["z"] = 12, ["name"] = "wool:black"}, {["x"] = 2, ["y"] = 7, ["param1"] = 15, ["z"] = 13, ["name"] = "wool:black"}, {["x"] = 2, ["y"] = 7, ["param1"] = 15, ["z"] = 14, ["name"] = "default:steelblock"}, {["x"] = 2, ["y"] = 8, ["param1"] = 15, ["z"] = 1, ["name"] = "default:steelblock"}, {["x"] = 2, ["y"] = 8, ["param1"] = 15, ["z"] = 2, ["name"] = "wool:black"}, {["x"] = 2, ["y"] = 8, ["param1"] = 15, ["z"] = 3, ["name"] = "wool:black"}, {["x"] = 2, ["y"] = 8, ["param1"] = 15, ["z"] = 4, ["name"] = "wool:black"}, {["x"] = 2, ["y"] = 8, ["param1"] = 15, ["z"] = 5, ["name"] = "wool:black"}, {["x"] = 2, ["y"] = 8, ["param1"] = 15, ["z"] = 6, ["name"] = "wool:black"}, {["x"] = 2, ["y"] = 8, ["param1"] = 15, ["z"] = 7, ["name"] = "wool:black"}, {["x"] = 2, ["y"] = 8, ["param1"] = 15, ["z"] = 8, ["name"] = "wool:black"}, {["x"] = 2, ["y"] = 8, ["param1"] = 15, ["z"] = 9, ["name"] = "wool:black"}, {["x"] = 2, ["y"] = 8, ["param1"] = 15, ["z"] = 10, ["name"] = "wool:black"}, {["x"] = 2, ["y"] = 8, ["param1"] = 15, ["z"] = 11, ["name"] = "wool:black"}, {["x"] = 2, ["y"] = 8, ["param1"] = 15, ["z"] = 12, ["name"] = "wool:black"}, {["x"] = 2, ["y"] = 8, ["param1"] = 15, ["z"] = 13, ["name"] = "wool:black"}, {["x"] = 2, ["y"] = 8, ["param1"] = 15, ["z"] = 14, ["name"] = "default:steelblock"}, {["x"] = 2, ["y"] = 9, ["param1"] = 15, ["z"] = 1, ["name"] = "default:steelblock"}, {["x"] = 2, ["y"] = 9, ["param1"] = 15, ["z"] = 2, ["name"] = "wool:black"}, {["x"] = 2, ["y"] = 9, ["param1"] = 15, ["z"] = 3, ["name"] = "wool:black"}, {["x"] = 2, ["y"] = 9, ["param1"] = 15, ["z"] = 4, ["name"] = "wool:black"}, {["x"] = 2, ["y"] = 9, ["param1"] = 15, ["z"] = 5, ["name"] = "wool:black"}, {["x"] = 2, ["y"] = 9, ["param1"] = 15, ["z"] = 6, ["name"] = "wool:black"}, {["x"] = 2, ["y"] = 9, ["param1"] = 15, ["z"] = 7, ["name"] = "wool:black"}, {["x"] = 2, ["y"] = 9, ["param1"] = 15, ["z"] = 8, ["name"] = "wool:black"}, {["x"] = 2, ["y"] = 9, ["param1"] = 15, ["z"] = 9, ["name"] = "wool:black"}, {["x"] = 2, ["y"] = 9, ["param1"] = 15, ["z"] = 10, ["name"] = "wool:black"}, {["x"] = 2, ["y"] = 9, ["param1"] = 15, ["z"] = 11, ["name"] = "wool:black"}, {["x"] = 2, ["y"] = 9, ["param1"] = 15, ["z"] = 12, ["name"] = "wool:black"}, {["x"] = 2, ["y"] = 9, ["param1"] = 15, ["z"] = 13, ["name"] = "wool:black"}, {["x"] = 2, ["y"] = 9, ["param1"] = 15, ["z"] = 14, ["name"] = "default:steelblock"}, {["x"] = 2, ["y"] = 10, ["param1"] = 15, ["z"] = 1, ["name"] = "default:steelblock"}, {["x"] = 2, ["y"] = 10, ["param1"] = 15, ["z"] = 2, ["name"] = "wool:black"}, {["x"] = 2, ["y"] = 10, ["param1"] = 15, ["z"] = 3, ["name"] = "wool:black"}, {["x"] = 2, ["y"] = 10, ["param1"] = 15, ["z"] = 4, ["name"] = "wool:black"}, {["x"] = 2, ["y"] = 10, ["param1"] = 15, ["z"] = 5, ["name"] = "wool:black"}, {["x"] = 2, ["y"] = 10, ["param1"] = 15, ["z"] = 6, ["name"] = "wool:black"}, {["x"] = 2, ["y"] = 10, ["param1"] = 15, ["z"] = 7, ["name"] = "wool:black"}, {["x"] = 2, ["y"] = 10, ["param1"] = 15, ["z"] = 8, ["name"] = "wool:black"}, {["x"] = 2, ["y"] = 10, ["param1"] = 15, ["z"] = 9, ["name"] = "wool:black"}, {["x"] = 2, ["y"] = 10, ["param1"] = 15, ["z"] = 10, ["name"] = "wool:black"}, {["x"] = 2, ["y"] = 10, ["param1"] = 15, ["z"] = 11, ["name"] = "wool:black"}, {["x"] = 2, ["y"] = 10, ["param1"] = 15, ["z"] = 12, ["name"] = "wool:black"}, {["x"] = 2, ["y"] = 10, ["param1"] = 15, ["z"] = 13, ["name"] = "wool:black"}, {["x"] = 2, ["y"] = 10, ["param1"] = 15, ["z"] = 14, ["name"] = "default:steelblock"}, {["x"] = 2, ["y"] = 11, ["param1"] = 15, ["z"] = 1, ["name"] = "default:steelblock"}, {["x"] = 2, ["y"] = 11, ["param1"] = 15, ["z"] = 2, ["name"] = "wool:black"}, {["x"] = 2, ["y"] = 11, ["param1"] = 15, ["z"] = 3, ["name"] = "wool:black"}, {["x"] = 2, ["y"] = 11, ["param1"] = 15, ["z"] = 4, ["name"] = "wool:black"}, {["x"] = 2, ["y"] = 11, ["param1"] = 15, ["z"] = 5, ["name"] = "wool:black"}, {["x"] = 2, ["y"] = 11, ["param1"] = 15, ["z"] = 6, ["name"] = "wool:black"}, {["x"] = 2, ["y"] = 11, ["param1"] = 15, ["z"] = 7, ["name"] = "wool:black"}, {["x"] = 2, ["y"] = 11, ["param1"] = 15, ["z"] = 8, ["name"] = "wool:black"}, {["x"] = 2, ["y"] = 11, ["param1"] = 15, ["z"] = 9, ["name"] = "wool:black"}, {["x"] = 2, ["y"] = 11, ["param1"] = 15, ["z"] = 10, ["name"] = "wool:black"}, {["x"] = 2, ["y"] = 11, ["param1"] = 15, ["z"] = 11, ["name"] = "wool:black"}, {["x"] = 2, ["y"] = 11, ["param1"] = 15, ["z"] = 12, ["name"] = "wool:black"}, {["x"] = 2, ["y"] = 11, ["param1"] = 15, ["z"] = 13, ["name"] = "wool:black"}, {["x"] = 2, ["y"] = 11, ["param1"] = 15, ["z"] = 14, ["name"] = "default:steelblock"}, {["x"] = 2, ["y"] = 12, ["param1"] = 15, ["z"] = 2, ["name"] = "wool:black"}, {["x"] = 2, ["y"] = 12, ["param1"] = 15, ["z"] = 3, ["name"] = "wool:black"}, {["x"] = 2, ["y"] = 12, ["param1"] = 15, ["z"] = 4, ["name"] = "wool:black"}, {["x"] = 2, ["y"] = 12, ["param1"] = 15, ["z"] = 5, ["name"] = "wool:black"}, {["x"] = 2, ["y"] = 12, ["param1"] = 15, ["z"] = 6, ["name"] = "wool:black"}, {["x"] = 2, ["y"] = 12, ["param1"] = 15, ["z"] = 7, ["name"] = "wool:black"}, {["x"] = 2, ["y"] = 12, ["param1"] = 15, ["z"] = 8, ["name"] = "wool:black"}, {["x"] = 2, ["y"] = 12, ["param1"] = 15, ["z"] = 9, ["name"] = "wool:black"}, {["x"] = 2, ["y"] = 12, ["param1"] = 15, ["z"] = 10, ["name"] = "wool:black"}, {["x"] = 2, ["y"] = 12, ["param1"] = 15, ["z"] = 11, ["name"] = "wool:black"}, {["x"] = 2, ["y"] = 12, ["param1"] = 15, ["z"] = 12, ["name"] = "wool:black"}, {["x"] = 2, ["y"] = 12, ["param1"] = 15, ["z"] = 13, ["name"] = "wool:black"}, {["x"] = 2, ["y"] = 13, ["param1"] = 15, ["z"] = 2, ["name"] = "wool:black"}, {["x"] = 2, ["y"] = 13, ["param1"] = 15, ["z"] = 3, ["name"] = "wool:black"}, {["x"] = 2, ["y"] = 13, ["param1"] = 15, ["z"] = 4, ["name"] = "wool:black"}, {["x"] = 2, ["y"] = 13, ["param1"] = 15, ["z"] = 5, ["name"] = "wool:black"}, {["x"] = 2, ["y"] = 13, ["param1"] = 15, ["z"] = 6, ["name"] = "wool:black"}, {["x"] = 2, ["y"] = 13, ["param1"] = 15, ["z"] = 7, ["name"] = "wool:black"}, {["x"] = 2, ["y"] = 13, ["param1"] = 15, ["z"] = 8, ["name"] = "wool:black"}, {["x"] = 2, ["y"] = 13, ["param1"] = 15, ["z"] = 9, ["name"] = "wool:black"}, {["x"] = 2, ["y"] = 13, ["param1"] = 15, ["z"] = 10, ["name"] = "wool:black"}, {["x"] = 2, ["y"] = 13, ["param1"] = 15, ["z"] = 11, ["name"] = "wool:black"}, {["x"] = 2, ["y"] = 13, ["param1"] = 15, ["z"] = 12, ["name"] = "wool:black"}, {["x"] = 2, ["y"] = 13, ["param1"] = 15, ["z"] = 13, ["name"] = "wool:black"}, {["x"] = 2, ["y"] = 14, ["z"] = 1, ["name"] = "wool:black"}, {["x"] = 2, ["y"] = 14, ["param1"] = 15, ["z"] = 2, ["name"] = "wool:black"}, {["x"] = 2, ["y"] = 14, ["param1"] = 15, ["z"] = 3, ["name"] = "wool:black"}, {["x"] = 2, ["y"] = 14, ["param1"] = 15, ["z"] = 4, ["name"] = "wool:black"}, {["x"] = 2, ["y"] = 14, ["param1"] = 15, ["z"] = 5, ["name"] = "wool:black"}, {["x"] = 2, ["y"] = 14, ["param1"] = 15, ["z"] = 6, ["name"] = "wool:black"}, {["x"] = 2, ["y"] = 14, ["param1"] = 15, ["z"] = 7, ["name"] = "wool:black"}, {["x"] = 2, ["y"] = 14, ["param1"] = 15, ["z"] = 8, ["name"] = "wool:black"}, {["x"] = 2, ["y"] = 14, ["param1"] = 15, ["z"] = 9, ["name"] = "wool:black"}, {["x"] = 2, ["y"] = 14, ["param1"] = 15, ["z"] = 10, ["name"] = "wool:black"}, {["x"] = 2, ["y"] = 14, ["param1"] = 15, ["z"] = 11, ["name"] = "wool:black"}, {["x"] = 2, ["y"] = 14, ["param1"] = 15, ["z"] = 12, ["name"] = "wool:black"}, {["x"] = 2, ["y"] = 14, ["param1"] = 15, ["z"] = 13, ["name"] = "wool:black"}, {["x"] = 2, ["y"] = 14, ["z"] = 14, ["name"] = "wool:black"}, {["x"] = 2, ["y"] = 15, ["z"] = 1, ["name"] = "wool:black"}, {["x"] = 2, ["y"] = 15, ["param1"] = 14, ["z"] = 2, ["name"] = "wool:black"}, {["x"] = 2, ["y"] = 15, ["param1"] = 14, ["z"] = 3, ["name"] = "wool:black"}, {["x"] = 2, ["y"] = 15, ["param1"] = 14, ["z"] = 4, ["name"] = "wool:black"}, {["x"] = 2, ["y"] = 15, ["param1"] = 14, ["z"] = 5, ["name"] = "wool:black"}, {["x"] = 2, ["y"] = 15, ["param1"] = 14, ["z"] = 6, ["name"] = "wool:black"}, {["x"] = 2, ["y"] = 15, ["param1"] = 14, ["z"] = 7, ["name"] = "wool:black"}, {["x"] = 2, ["y"] = 15, ["param1"] = 14, ["z"] = 8, ["name"] = "wool:black"}, {["x"] = 2, ["y"] = 15, ["param1"] = 14, ["z"] = 9, ["name"] = "wool:black"}, {["x"] = 2, ["y"] = 15, ["param1"] = 14, ["z"] = 10, ["name"] = "wool:black"}, {["x"] = 2, ["y"] = 15, ["param1"] = 14, ["z"] = 11, ["name"] = "wool:black"}, {["x"] = 2, ["y"] = 15, ["param1"] = 14, ["z"] = 12, ["name"] = "wool:black"}, {["x"] = 2, ["y"] = 15, ["param1"] = 14, ["z"] = 13, ["name"] = "wool:black"}, {["x"] = 2, ["y"] = 15, ["z"] = 14, ["name"] = "wool:black"}, {["x"] = 3, ["y"] = 0, ["z"] = 2, ["name"] = "wool:black"}, {["x"] = 3, ["y"] = 0, ["param1"] = 15, ["z"] = 3, ["name"] = "wool:black"}, {["x"] = 3, ["y"] = 0, ["param1"] = 15, ["z"] = 4, ["name"] = "wool:black"}, {["x"] = 3, ["y"] = 0, ["param1"] = 15, ["z"] = 5, ["name"] = "wool:black"}, {["x"] = 3, ["y"] = 0, ["param1"] = 15, ["z"] = 6, ["name"] = "wool:black"}, {["x"] = 3, ["y"] = 0, ["param1"] = 15, ["z"] = 7, ["name"] = "wool:black"}, {["x"] = 3, ["y"] = 0, ["param1"] = 15, ["z"] = 8, ["name"] = "wool:black"}, {["x"] = 3, ["y"] = 0, ["param1"] = 15, ["z"] = 9, ["name"] = "wool:black"}, {["x"] = 3, ["y"] = 0, ["param1"] = 15, ["z"] = 10, ["name"] = "wool:black"}, {["x"] = 3, ["y"] = 0, ["param1"] = 14, ["z"] = 11, ["name"] = "wool:black"}, {["x"] = 3, ["y"] = 0, ["param1"] = 14, ["z"] = 12, ["name"] = "wool:black"}, {["x"] = 3, ["y"] = 0, ["param1"] = 14, ["z"] = 13, ["name"] = "wool:black"}, {["x"] = 3, ["y"] = 1, ["z"] = 2, ["name"] = "wool:black"}, {["x"] = 3, ["y"] = 1, ["param1"] = 15, ["z"] = 3, ["name"] = "wool:black"}, {["x"] = 3, ["y"] = 1, ["param1"] = 15, ["z"] = 4, ["name"] = "wool:black"}, {["x"] = 3, ["y"] = 1, ["param1"] = 15, ["z"] = 5, ["name"] = "wool:black"}, {["x"] = 3, ["y"] = 1, ["param1"] = 15, ["z"] = 6, ["name"] = "wool:black"}, {["x"] = 3, ["y"] = 1, ["param1"] = 15, ["z"] = 7, ["name"] = "wool:black"}, {["x"] = 3, ["y"] = 1, ["param1"] = 15, ["z"] = 8, ["name"] = "wool:black"}, {["x"] = 3, ["y"] = 1, ["param1"] = 15, ["z"] = 9, ["name"] = "wool:black"}, {["x"] = 3, ["y"] = 1, ["param1"] = 15, ["z"] = 10, ["name"] = "wool:black"}, {["x"] = 3, ["y"] = 1, ["param1"] = 15, ["z"] = 11, ["name"] = "wool:black"}, {["x"] = 3, ["y"] = 1, ["param1"] = 15, ["z"] = 12, ["name"] = "wool:black"}, {["x"] = 3, ["y"] = 1, ["param1"] = 15, ["z"] = 13, ["name"] = "wool:black"}, {["x"] = 3, ["y"] = 2, ["param1"] = 15, ["z"] = 1, ["name"] = "default:steelblock"}, {["x"] = 3, ["y"] = 2, ["param1"] = 15, ["z"] = 2, ["name"] = "wool:black"}, {["x"] = 3, ["y"] = 2, ["param1"] = 15, ["z"] = 3, ["name"] = "wool:black"}, {["x"] = 3, ["y"] = 2, ["param1"] = 15, ["z"] = 4, ["name"] = "wool:black"}, {["x"] = 3, ["y"] = 2, ["param1"] = 15, ["z"] = 5, ["name"] = "wool:black"}, {["x"] = 3, ["y"] = 2, ["param1"] = 15, ["z"] = 6, ["name"] = "wool:black"}, {["x"] = 3, ["y"] = 2, ["param1"] = 15, ["z"] = 7, ["name"] = "wool:black"}, {["x"] = 3, ["y"] = 2, ["param1"] = 15, ["z"] = 8, ["name"] = "wool:black"}, {["x"] = 3, ["y"] = 2, ["param1"] = 15, ["z"] = 9, ["name"] = "wool:black"}, {["x"] = 3, ["y"] = 2, ["param1"] = 15, ["z"] = 10, ["name"] = "wool:black"}, {["x"] = 3, ["y"] = 2, ["param1"] = 15, ["z"] = 11, ["name"] = "wool:black"}, {["x"] = 3, ["y"] = 2, ["param1"] = 15, ["z"] = 12, ["name"] = "wool:black"}, {["x"] = 3, ["y"] = 2, ["param1"] = 15, ["z"] = 13, ["name"] = "wool:black"}, {["x"] = 3, ["y"] = 2, ["param1"] = 15, ["z"] = 14, ["name"] = "default:steelblock"}, {["x"] = 3, ["y"] = 3, ["param1"] = 15, ["z"] = 1, ["name"] = "default:steelblock"}, {["x"] = 3, ["y"] = 3, ["param1"] = 15, ["z"] = 2, ["name"] = "wool:black"}, {["x"] = 3, ["y"] = 3, ["param1"] = 15, ["z"] = 3, ["name"] = "wool:black"}, {["x"] = 3, ["y"] = 3, ["param1"] = 15, ["z"] = 4, ["name"] = "wool:black"}, {["x"] = 3, ["y"] = 3, ["param1"] = 15, ["z"] = 5, ["name"] = "wool:black"}, {["x"] = 3, ["y"] = 3, ["param1"] = 15, ["z"] = 6, ["name"] = "wool:black"}, {["x"] = 3, ["y"] = 3, ["param1"] = 15, ["z"] = 7, ["name"] = "wool:black"}, {["x"] = 3, ["y"] = 3, ["param1"] = 15, ["z"] = 8, ["name"] = "wool:black"}, {["x"] = 3, ["y"] = 3, ["param1"] = 15, ["z"] = 9, ["name"] = "wool:black"}, {["x"] = 3, ["y"] = 3, ["param1"] = 15, ["z"] = 10, ["name"] = "wool:black"}, {["x"] = 3, ["y"] = 3, ["param1"] = 15, ["z"] = 11, ["name"] = "wool:black"}, {["x"] = 3, ["y"] = 3, ["param1"] = 15, ["z"] = 12, ["name"] = "wool:black"}, {["x"] = 3, ["y"] = 3, ["param1"] = 15, ["z"] = 13, ["name"] = "wool:black"}, {["x"] = 3, ["y"] = 3, ["param1"] = 15, ["z"] = 14, ["name"] = "default:steelblock"}, {["x"] = 3, ["y"] = 4, ["param1"] = 15, ["z"] = 1, ["name"] = "default:steelblock"}, {["x"] = 3, ["y"] = 4, ["param1"] = 15, ["z"] = 2, ["name"] = "wool:black"}, {["x"] = 3, ["y"] = 4, ["param1"] = 15, ["z"] = 3, ["name"] = "wool:black"}, {["x"] = 3, ["y"] = 4, ["param1"] = 15, ["z"] = 4, ["name"] = "wool:black"}, {["x"] = 3, ["y"] = 4, ["param1"] = 15, ["z"] = 5, ["name"] = "wool:black"}, {["x"] = 3, ["y"] = 4, ["param1"] = 15, ["z"] = 6, ["name"] = "wool:black"}, {["x"] = 3, ["y"] = 4, ["param1"] = 15, ["z"] = 7, ["name"] = "wool:black"}, {["x"] = 3, ["y"] = 4, ["param1"] = 15, ["z"] = 8, ["name"] = "wool:black"}, {["x"] = 3, ["y"] = 4, ["param1"] = 15, ["z"] = 9, ["name"] = "wool:black"}, {["x"] = 3, ["y"] = 4, ["param1"] = 15, ["z"] = 10, ["name"] = "wool:black"}, {["x"] = 3, ["y"] = 4, ["param1"] = 15, ["z"] = 11, ["name"] = "wool:black"}, {["x"] = 3, ["y"] = 4, ["param1"] = 15, ["z"] = 12, ["name"] = "wool:black"}, {["x"] = 3, ["y"] = 4, ["param1"] = 15, ["z"] = 13, ["name"] = "wool:black"}, {["x"] = 3, ["y"] = 4, ["param1"] = 15, ["z"] = 14, ["name"] = "default:steelblock"}, {["x"] = 3, ["y"] = 5, ["param1"] = 15, ["z"] = 1, ["name"] = "default:steelblock"}, {["x"] = 3, ["y"] = 5, ["param1"] = 15, ["z"] = 2, ["name"] = "wool:black"}, {["x"] = 3, ["y"] = 5, ["param1"] = 15, ["z"] = 3, ["name"] = "wool:black"}, {["x"] = 3, ["y"] = 5, ["param1"] = 15, ["z"] = 4, ["name"] = "wool:black"}, {["x"] = 3, ["y"] = 5, ["param1"] = 15, ["z"] = 5, ["name"] = "wool:black"}, {["x"] = 3, ["y"] = 5, ["param1"] = 15, ["z"] = 6, ["name"] = "wool:black"}, {["x"] = 3, ["y"] = 5, ["param1"] = 15, ["z"] = 7, ["name"] = "wool:black"}, {["x"] = 3, ["y"] = 5, ["param1"] = 15, ["z"] = 8, ["name"] = "wool:black"}, {["x"] = 3, ["y"] = 5, ["param1"] = 15, ["z"] = 9, ["name"] = "wool:black"}, {["x"] = 3, ["y"] = 5, ["param1"] = 15, ["z"] = 10, ["name"] = "wool:black"}, {["x"] = 3, ["y"] = 5, ["param1"] = 15, ["z"] = 11, ["name"] = "wool:black"}, {["x"] = 3, ["y"] = 5, ["param1"] = 15, ["z"] = 12, ["name"] = "wool:black"}, {["x"] = 3, ["y"] = 5, ["param1"] = 15, ["z"] = 13, ["name"] = "wool:black"}, {["x"] = 3, ["y"] = 5, ["param1"] = 15, ["z"] = 14, ["name"] = "default:steelblock"}, {["x"] = 3, ["y"] = 6, ["param1"] = 15, ["z"] = 1, ["name"] = "default:steelblock"}, {["x"] = 3, ["y"] = 6, ["param1"] = 15, ["z"] = 2, ["name"] = "wool:black"}, {["x"] = 3, ["y"] = 6, ["param1"] = 15, ["z"] = 3, ["name"] = "wool:black"}, {["x"] = 3, ["y"] = 6, ["param1"] = 15, ["z"] = 4, ["name"] = "wool:black"}, {["x"] = 3, ["y"] = 6, ["param1"] = 15, ["z"] = 5, ["name"] = "wool:black"}, {["x"] = 3, ["y"] = 6, ["param1"] = 15, ["z"] = 6, ["name"] = "wool:black"}, {["x"] = 3, ["y"] = 6, ["param1"] = 15, ["z"] = 7, ["name"] = "wool:black"}, {["x"] = 3, ["y"] = 6, ["param1"] = 15, ["z"] = 8, ["name"] = "wool:black"}, {["x"] = 3, ["y"] = 6, ["param1"] = 15, ["z"] = 9, ["name"] = "wool:black"}, {["x"] = 3, ["y"] = 6, ["param1"] = 15, ["z"] = 10, ["name"] = "wool:black"}, {["x"] = 3, ["y"] = 6, ["param1"] = 15, ["z"] = 11, ["name"] = "wool:black"}, {["x"] = 3, ["y"] = 6, ["param1"] = 15, ["z"] = 12, ["name"] = "wool:black"}, {["x"] = 3, ["y"] = 6, ["param1"] = 15, ["z"] = 13, ["name"] = "wool:black"}, {["x"] = 3, ["y"] = 6, ["param1"] = 15, ["z"] = 14, ["name"] = "default:steelblock"}, {["x"] = 3, ["y"] = 7, ["param1"] = 15, ["z"] = 1, ["name"] = "default:steelblock"}, {["x"] = 3, ["y"] = 7, ["param1"] = 15, ["z"] = 2, ["name"] = "wool:black"}, {["x"] = 3, ["y"] = 7, ["param1"] = 15, ["z"] = 3, ["name"] = "wool:black"}, {["x"] = 3, ["y"] = 7, ["param1"] = 15, ["z"] = 4, ["name"] = "wool:black"}, {["x"] = 3, ["y"] = 7, ["param1"] = 15, ["z"] = 5, ["name"] = "wool:black"}, {["x"] = 3, ["y"] = 7, ["param1"] = 15, ["z"] = 6, ["name"] = "wool:black"}, {["x"] = 3, ["y"] = 7, ["param1"] = 15, ["z"] = 7, ["name"] = "wool:black"}, {["x"] = 3, ["y"] = 7, ["param1"] = 15, ["z"] = 8, ["name"] = "wool:black"}, {["x"] = 3, ["y"] = 7, ["param1"] = 15, ["z"] = 9, ["name"] = "wool:black"}, {["x"] = 3, ["y"] = 7, ["param1"] = 15, ["z"] = 10, ["name"] = "wool:black"}, {["x"] = 3, ["y"] = 7, ["param1"] = 15, ["z"] = 11, ["name"] = "wool:black"}, {["x"] = 3, ["y"] = 7, ["param1"] = 15, ["z"] = 12, ["name"] = "wool:black"}, {["x"] = 3, ["y"] = 7, ["param1"] = 15, ["z"] = 13, ["name"] = "wool:black"}, {["x"] = 3, ["y"] = 7, ["param1"] = 15, ["z"] = 14, ["name"] = "default:steelblock"}, {["x"] = 3, ["y"] = 8, ["param1"] = 15, ["z"] = 1, ["name"] = "default:steelblock"}, {["x"] = 3, ["y"] = 8, ["param1"] = 15, ["z"] = 2, ["name"] = "wool:black"}, {["x"] = 3, ["y"] = 8, ["param1"] = 15, ["z"] = 3, ["name"] = "wool:black"}, {["x"] = 3, ["y"] = 8, ["param1"] = 15, ["z"] = 4, ["name"] = "wool:black"}, {["x"] = 3, ["y"] = 8, ["param1"] = 15, ["z"] = 5, ["name"] = "wool:black"}, {["x"] = 3, ["y"] = 8, ["param1"] = 15, ["z"] = 6, ["name"] = "wool:black"}, {["x"] = 3, ["y"] = 8, ["param1"] = 15, ["z"] = 7, ["name"] = "wool:black"}, {["x"] = 3, ["y"] = 8, ["param1"] = 15, ["z"] = 8, ["name"] = "wool:black"}, {["x"] = 3, ["y"] = 8, ["param1"] = 15, ["z"] = 9, ["name"] = "wool:black"}, {["x"] = 3, ["y"] = 8, ["param1"] = 15, ["z"] = 10, ["name"] = "wool:black"}, {["x"] = 3, ["y"] = 8, ["param1"] = 15, ["z"] = 11, ["name"] = "wool:black"}, {["x"] = 3, ["y"] = 8, ["param1"] = 15, ["z"] = 12, ["name"] = "wool:black"}, {["x"] = 3, ["y"] = 8, ["param1"] = 15, ["z"] = 13, ["name"] = "wool:black"}, {["x"] = 3, ["y"] = 8, ["param1"] = 15, ["z"] = 14, ["name"] = "default:steelblock"}, {["x"] = 3, ["y"] = 9, ["param1"] = 15, ["z"] = 1, ["name"] = "default:steelblock"}, {["x"] = 3, ["y"] = 9, ["param1"] = 15, ["z"] = 2, ["name"] = "wool:black"}, {["x"] = 3, ["y"] = 9, ["param1"] = 15, ["z"] = 3, ["name"] = "wool:black"}, {["x"] = 3, ["y"] = 9, ["param1"] = 15, ["z"] = 4, ["name"] = "wool:black"}, {["x"] = 3, ["y"] = 9, ["param1"] = 15, ["z"] = 5, ["name"] = "wool:black"}, {["x"] = 3, ["y"] = 9, ["param1"] = 15, ["z"] = 6, ["name"] = "wool:black"}, {["x"] = 3, ["y"] = 9, ["param1"] = 15, ["z"] = 7, ["name"] = "wool:black"}, {["x"] = 3, ["y"] = 9, ["param1"] = 15, ["z"] = 8, ["name"] = "wool:black"}, {["x"] = 3, ["y"] = 9, ["param1"] = 15, ["z"] = 9, ["name"] = "wool:black"}, {["x"] = 3, ["y"] = 9, ["param1"] = 15, ["z"] = 10, ["name"] = "wool:black"}, {["x"] = 3, ["y"] = 9, ["param1"] = 15, ["z"] = 11, ["name"] = "wool:black"}, {["x"] = 3, ["y"] = 9, ["param1"] = 15, ["z"] = 12, ["name"] = "wool:black"}, {["x"] = 3, ["y"] = 9, ["param1"] = 15, ["z"] = 13, ["name"] = "wool:black"}, {["x"] = 3, ["y"] = 9, ["param1"] = 15, ["z"] = 14, ["name"] = "default:steelblock"}, {["x"] = 3, ["y"] = 10, ["param1"] = 15, ["z"] = 1, ["name"] = "default:steelblock"}, {["x"] = 3, ["y"] = 10, ["param1"] = 15, ["z"] = 2, ["name"] = "wool:black"}, {["x"] = 3, ["y"] = 10, ["param1"] = 15, ["z"] = 3, ["name"] = "wool:black"}, {["x"] = 3, ["y"] = 10, ["param1"] = 15, ["z"] = 4, ["name"] = "wool:black"}, {["x"] = 3, ["y"] = 10, ["param1"] = 15, ["z"] = 5, ["name"] = "wool:black"}, {["x"] = 3, ["y"] = 10, ["param1"] = 15, ["z"] = 6, ["name"] = "wool:black"}, {["x"] = 3, ["y"] = 10, ["param1"] = 15, ["z"] = 7, ["name"] = "wool:black"}, {["x"] = 3, ["y"] = 10, ["param1"] = 15, ["z"] = 8, ["name"] = "wool:black"}, {["x"] = 3, ["y"] = 10, ["param1"] = 15, ["z"] = 9, ["name"] = "wool:black"}, {["x"] = 3, ["y"] = 10, ["param1"] = 15, ["z"] = 10, ["name"] = "wool:black"}, {["x"] = 3, ["y"] = 10, ["param1"] = 15, ["z"] = 11, ["name"] = "wool:black"}, {["x"] = 3, ["y"] = 10, ["param1"] = 15, ["z"] = 12, ["name"] = "wool:black"}, {["x"] = 3, ["y"] = 10, ["param1"] = 15, ["z"] = 13, ["name"] = "wool:black"}, {["x"] = 3, ["y"] = 10, ["param1"] = 15, ["z"] = 14, ["name"] = "default:steelblock"}, {["x"] = 3, ["y"] = 11, ["param1"] = 15, ["z"] = 1, ["name"] = "default:steelblock"}, {["x"] = 3, ["y"] = 11, ["param1"] = 15, ["z"] = 2, ["name"] = "wool:black"}, {["x"] = 3, ["y"] = 11, ["param1"] = 15, ["z"] = 3, ["name"] = "wool:black"}, {["x"] = 3, ["y"] = 11, ["param1"] = 15, ["z"] = 4, ["name"] = "wool:black"}, {["x"] = 3, ["y"] = 11, ["param1"] = 15, ["z"] = 5, ["name"] = "wool:black"}, {["x"] = 3, ["y"] = 11, ["param1"] = 15, ["z"] = 6, ["name"] = "wool:black"}, {["x"] = 3, ["y"] = 11, ["param1"] = 15, ["z"] = 7, ["name"] = "wool:black"}, {["x"] = 3, ["y"] = 11, ["param1"] = 15, ["z"] = 8, ["name"] = "wool:black"}, {["x"] = 3, ["y"] = 11, ["param1"] = 15, ["z"] = 9, ["name"] = "wool:black"}, {["x"] = 3, ["y"] = 11, ["param1"] = 15, ["z"] = 10, ["name"] = "wool:black"}, {["x"] = 3, ["y"] = 11, ["param1"] = 15, ["z"] = 11, ["name"] = "wool:black"}, {["x"] = 3, ["y"] = 11, ["param1"] = 15, ["z"] = 12, ["name"] = "wool:black"}, {["x"] = 3, ["y"] = 11, ["param1"] = 15, ["z"] = 13, ["name"] = "wool:black"}, {["x"] = 3, ["y"] = 11, ["param1"] = 15, ["z"] = 14, ["name"] = "default:steelblock"}, {["x"] = 3, ["y"] = 12, ["param1"] = 15, ["z"] = 2, ["name"] = "wool:black"}, {["x"] = 3, ["y"] = 12, ["param1"] = 15, ["z"] = 3, ["name"] = "wool:black"}, {["x"] = 3, ["y"] = 12, ["param1"] = 15, ["z"] = 4, ["name"] = "wool:black"}, {["x"] = 3, ["y"] = 12, ["param1"] = 15, ["z"] = 5, ["name"] = "wool:black"}, {["x"] = 3, ["y"] = 12, ["param1"] = 15, ["z"] = 6, ["name"] = "wool:black"}, {["x"] = 3, ["y"] = 12, ["param1"] = 15, ["z"] = 7, ["name"] = "wool:black"}, {["x"] = 3, ["y"] = 12, ["param1"] = 15, ["z"] = 8, ["name"] = "wool:black"}, {["x"] = 3, ["y"] = 12, ["param1"] = 15, ["z"] = 9, ["name"] = "wool:black"}, {["x"] = 3, ["y"] = 12, ["param1"] = 15, ["z"] = 10, ["name"] = "wool:black"}, {["x"] = 3, ["y"] = 12, ["param1"] = 15, ["z"] = 11, ["name"] = "wool:black"}, {["x"] = 3, ["y"] = 12, ["param1"] = 15, ["z"] = 12, ["name"] = "wool:black"}, {["x"] = 3, ["y"] = 12, ["param1"] = 15, ["z"] = 13, ["name"] = "wool:black"}, {["x"] = 3, ["y"] = 13, ["param1"] = 15, ["z"] = 2, ["name"] = "wool:black"}, {["x"] = 3, ["y"] = 13, ["param1"] = 15, ["z"] = 3, ["name"] = "wool:black"}, {["x"] = 3, ["y"] = 13, ["param1"] = 15, ["z"] = 4, ["name"] = "wool:black"}, {["x"] = 3, ["y"] = 13, ["param1"] = 15, ["z"] = 5, ["name"] = "wool:black"}, {["x"] = 3, ["y"] = 13, ["param1"] = 15, ["z"] = 6, ["name"] = "wool:black"}, {["x"] = 3, ["y"] = 13, ["param1"] = 15, ["z"] = 7, ["name"] = "wool:black"}, {["x"] = 3, ["y"] = 13, ["param1"] = 15, ["z"] = 8, ["name"] = "wool:black"}, {["x"] = 3, ["y"] = 13, ["param1"] = 15, ["z"] = 9, ["name"] = "wool:black"}, {["x"] = 3, ["y"] = 13, ["param1"] = 15, ["z"] = 10, ["name"] = "wool:black"}, {["x"] = 3, ["y"] = 13, ["param1"] = 15, ["z"] = 11, ["name"] = "wool:black"}, {["x"] = 3, ["y"] = 13, ["param1"] = 15, ["z"] = 12, ["name"] = "wool:black"}, {["x"] = 3, ["y"] = 13, ["param1"] = 15, ["z"] = 13, ["name"] = "wool:black"}, {["x"] = 3, ["y"] = 14, ["z"] = 1, ["name"] = "wool:black"}, {["x"] = 3, ["y"] = 14, ["param1"] = 15, ["z"] = 2, ["name"] = "wool:black"}, {["x"] = 3, ["y"] = 14, ["param1"] = 15, ["z"] = 3, ["name"] = "wool:black"}, {["x"] = 3, ["y"] = 14, ["param1"] = 15, ["z"] = 4, ["name"] = "wool:black"}, {["x"] = 3, ["y"] = 14, ["param1"] = 15, ["z"] = 5, ["name"] = "wool:black"}, {["x"] = 3, ["y"] = 14, ["param1"] = 15, ["z"] = 6, ["name"] = "wool:black"}, {["x"] = 3, ["y"] = 14, ["param1"] = 15, ["z"] = 7, ["name"] = "wool:black"}, {["x"] = 3, ["y"] = 14, ["param1"] = 15, ["z"] = 8, ["name"] = "wool:black"}, {["x"] = 3, ["y"] = 14, ["param1"] = 15, ["z"] = 9, ["name"] = "wool:black"}, {["x"] = 3, ["y"] = 14, ["param1"] = 15, ["z"] = 10, ["name"] = "wool:black"}, {["x"] = 3, ["y"] = 14, ["param1"] = 15, ["z"] = 11, ["name"] = "wool:black"}, {["x"] = 3, ["y"] = 14, ["param1"] = 15, ["z"] = 12, ["name"] = "wool:black"}, {["x"] = 3, ["y"] = 14, ["param1"] = 15, ["z"] = 13, ["name"] = "wool:black"}, {["x"] = 3, ["y"] = 14, ["z"] = 14, ["name"] = "wool:black"}, {["x"] = 3, ["y"] = 15, ["z"] = 1, ["name"] = "wool:black"}, {["x"] = 3, ["y"] = 15, ["param1"] = 14, ["z"] = 2, ["name"] = "wool:black"}, {["x"] = 3, ["y"] = 15, ["param1"] = 14, ["z"] = 3, ["name"] = "wool:black"}, {["x"] = 3, ["y"] = 15, ["param1"] = 14, ["z"] = 4, ["name"] = "wool:black"}, {["x"] = 3, ["y"] = 15, ["param1"] = 14, ["z"] = 5, ["name"] = "wool:black"}, {["x"] = 3, ["y"] = 15, ["param1"] = 14, ["z"] = 6, ["name"] = "wool:black"}, {["x"] = 3, ["y"] = 15, ["param1"] = 14, ["z"] = 7, ["name"] = "wool:black"}, {["x"] = 3, ["y"] = 15, ["param1"] = 14, ["z"] = 8, ["name"] = "wool:black"}, {["x"] = 3, ["y"] = 15, ["param1"] = 14, ["z"] = 9, ["name"] = "wool:black"}, {["x"] = 3, ["y"] = 15, ["param1"] = 14, ["z"] = 10, ["name"] = "wool:black"}, {["x"] = 3, ["y"] = 15, ["param1"] = 14, ["z"] = 11, ["name"] = "wool:black"}, {["x"] = 3, ["y"] = 15, ["param1"] = 14, ["z"] = 12, ["name"] = "wool:black"}, {["x"] = 3, ["y"] = 15, ["param1"] = 14, ["z"] = 13, ["name"] = "wool:black"}, {["x"] = 3, ["y"] = 15, ["z"] = 14, ["name"] = "wool:black"}, {["x"] = 4, ["y"] = 0, ["z"] = 2, ["name"] = "wool:black"}, {["x"] = 4, ["y"] = 0, ["param1"] = 15, ["z"] = 3, ["name"] = "wool:black"}, {["x"] = 4, ["y"] = 0, ["param1"] = 15, ["z"] = 4, ["name"] = "wool:black"}, {["x"] = 4, ["y"] = 0, ["param1"] = 15, ["z"] = 5, ["name"] = "wool:black"}, {["x"] = 4, ["y"] = 0, ["param1"] = 15, ["z"] = 6, ["name"] = "wool:black"}, {["x"] = 4, ["y"] = 0, ["param1"] = 15, ["z"] = 7, ["name"] = "wool:black"}, {["x"] = 4, ["y"] = 0, ["param1"] = 15, ["z"] = 8, ["name"] = "wool:black"}, {["x"] = 4, ["y"] = 0, ["param1"] = 15, ["z"] = 9, ["name"] = "wool:black"}, {["x"] = 4, ["y"] = 0, ["param1"] = 15, ["z"] = 10, ["name"] = "wool:black"}, {["x"] = 4, ["y"] = 0, ["param1"] = 14, ["z"] = 11, ["name"] = "wool:black"}, {["x"] = 4, ["y"] = 0, ["param1"] = 14, ["z"] = 12, ["name"] = "wool:black"}, {["x"] = 4, ["y"] = 0, ["param1"] = 14, ["z"] = 13, ["name"] = "wool:black"}, {["x"] = 4, ["y"] = 1, ["z"] = 2, ["name"] = "wool:black"}, {["x"] = 4, ["y"] = 1, ["param1"] = 15, ["z"] = 3, ["name"] = "wool:black"}, {["x"] = 4, ["y"] = 1, ["param1"] = 15, ["z"] = 4, ["name"] = "wool:black"}, {["x"] = 4, ["y"] = 1, ["param1"] = 15, ["z"] = 5, ["name"] = "wool:black"}, {["x"] = 4, ["y"] = 1, ["param1"] = 15, ["z"] = 6, ["name"] = "wool:black"}, {["x"] = 4, ["y"] = 1, ["param1"] = 15, ["z"] = 7, ["name"] = "wool:black"}, {["x"] = 4, ["y"] = 1, ["param1"] = 15, ["z"] = 8, ["name"] = "wool:black"}, {["x"] = 4, ["y"] = 1, ["param1"] = 15, ["z"] = 9, ["name"] = "wool:black"}, {["x"] = 4, ["y"] = 1, ["param1"] = 15, ["z"] = 10, ["name"] = "wool:black"}, {["x"] = 4, ["y"] = 1, ["param1"] = 15, ["z"] = 11, ["name"] = "wool:black"}, {["x"] = 4, ["y"] = 1, ["param1"] = 15, ["z"] = 12, ["name"] = "wool:black"}, {["x"] = 4, ["y"] = 1, ["param1"] = 15, ["z"] = 13, ["name"] = "wool:black"}, {["x"] = 4, ["y"] = 2, ["param1"] = 15, ["z"] = 1, ["name"] = "default:steelblock"}, {["x"] = 4, ["y"] = 2, ["param1"] = 15, ["z"] = 2, ["name"] = "wool:black"}, {["x"] = 4, ["y"] = 2, ["param1"] = 15, ["z"] = 3, ["name"] = "wool:black"}, {["x"] = 4, ["y"] = 2, ["param1"] = 15, ["z"] = 4, ["name"] = "wool:black"}, {["x"] = 4, ["y"] = 2, ["param1"] = 15, ["z"] = 5, ["name"] = "wool:black"}, {["x"] = 4, ["y"] = 2, ["param1"] = 15, ["z"] = 6, ["name"] = "wool:black"}, {["x"] = 4, ["y"] = 2, ["param1"] = 15, ["z"] = 7, ["name"] = "wool:black"}, {["x"] = 4, ["y"] = 2, ["param1"] = 15, ["z"] = 8, ["name"] = "wool:black"}, {["x"] = 4, ["y"] = 2, ["param1"] = 15, ["z"] = 9, ["name"] = "wool:black"}, {["x"] = 4, ["y"] = 2, ["param1"] = 15, ["z"] = 10, ["name"] = "wool:black"}, {["x"] = 4, ["y"] = 2, ["param1"] = 15, ["z"] = 11, ["name"] = "wool:black"}, {["x"] = 4, ["y"] = 2, ["param1"] = 15, ["z"] = 12, ["name"] = "wool:black"}, {["x"] = 4, ["y"] = 2, ["param1"] = 15, ["z"] = 13, ["name"] = "wool:black"}, {["x"] = 4, ["y"] = 2, ["param1"] = 15, ["z"] = 14, ["name"] = "default:steelblock"}, {["x"] = 4, ["y"] = 3, ["param1"] = 15, ["z"] = 1, ["name"] = "default:steelblock"}, {["x"] = 4, ["y"] = 3, ["param1"] = 15, ["z"] = 2, ["name"] = "wool:black"}, {["x"] = 4, ["y"] = 3, ["param1"] = 15, ["z"] = 3, ["name"] = "wool:black"}, {["x"] = 4, ["y"] = 3, ["param1"] = 15, ["z"] = 4, ["name"] = "wool:black"}, {["x"] = 4, ["y"] = 3, ["param1"] = 15, ["z"] = 5, ["name"] = "wool:black"}, {["x"] = 4, ["y"] = 3, ["param1"] = 15, ["z"] = 6, ["name"] = "wool:black"}, {["x"] = 4, ["y"] = 3, ["param1"] = 15, ["z"] = 7, ["name"] = "wool:black"}, {["x"] = 4, ["y"] = 3, ["param1"] = 15, ["z"] = 8, ["name"] = "wool:black"}, {["x"] = 4, ["y"] = 3, ["param1"] = 15, ["z"] = 9, ["name"] = "wool:black"}, {["x"] = 4, ["y"] = 3, ["param1"] = 15, ["z"] = 10, ["name"] = "wool:black"}, {["x"] = 4, ["y"] = 3, ["param1"] = 15, ["z"] = 11, ["name"] = "wool:black"}, {["x"] = 4, ["y"] = 3, ["param1"] = 15, ["z"] = 12, ["name"] = "wool:black"}, {["x"] = 4, ["y"] = 3, ["param1"] = 15, ["z"] = 13, ["name"] = "wool:black"}, {["x"] = 4, ["y"] = 3, ["param1"] = 15, ["z"] = 14, ["name"] = "default:steelblock"}, {["x"] = 4, ["y"] = 4, ["param1"] = 15, ["z"] = 1, ["name"] = "default:steelblock"}, {["x"] = 4, ["y"] = 4, ["param1"] = 15, ["z"] = 2, ["name"] = "wool:black"}, {["x"] = 4, ["y"] = 4, ["param1"] = 15, ["z"] = 3, ["name"] = "wool:black"}, {["x"] = 4, ["y"] = 4, ["param1"] = 15, ["z"] = 4, ["name"] = "wool:black"}, {["x"] = 4, ["y"] = 4, ["param1"] = 15, ["z"] = 5, ["name"] = "wool:black"}, {["x"] = 4, ["y"] = 4, ["param1"] = 15, ["z"] = 6, ["name"] = "wool:black"}, {["x"] = 4, ["y"] = 4, ["param1"] = 15, ["z"] = 7, ["name"] = "wool:black"}, {["x"] = 4, ["y"] = 4, ["param1"] = 15, ["z"] = 8, ["name"] = "wool:black"}, {["x"] = 4, ["y"] = 4, ["param1"] = 15, ["z"] = 9, ["name"] = "wool:black"}, {["x"] = 4, ["y"] = 4, ["param1"] = 15, ["z"] = 10, ["name"] = "wool:black"}, {["x"] = 4, ["y"] = 4, ["param1"] = 15, ["z"] = 11, ["name"] = "wool:black"}, {["x"] = 4, ["y"] = 4, ["param1"] = 15, ["z"] = 12, ["name"] = "wool:black"}, {["x"] = 4, ["y"] = 4, ["param1"] = 15, ["z"] = 13, ["name"] = "wool:black"}, {["x"] = 4, ["y"] = 4, ["param1"] = 15, ["z"] = 14, ["name"] = "default:steelblock"}, {["x"] = 4, ["y"] = 5, ["param1"] = 15, ["z"] = 1, ["name"] = "default:steelblock"}, {["x"] = 4, ["y"] = 5, ["param1"] = 15, ["z"] = 2, ["name"] = "wool:black"}, {["x"] = 4, ["y"] = 5, ["param1"] = 15, ["z"] = 3, ["name"] = "wool:black"}, {["x"] = 4, ["y"] = 5, ["param1"] = 15, ["z"] = 4, ["name"] = "wool:black"}, {["x"] = 4, ["y"] = 5, ["param1"] = 15, ["z"] = 5, ["name"] = "wool:black"}, {["x"] = 4, ["y"] = 5, ["param1"] = 15, ["z"] = 6, ["name"] = "wool:black"}, {["x"] = 4, ["y"] = 5, ["param1"] = 15, ["z"] = 7, ["name"] = "wool:black"}, {["x"] = 4, ["y"] = 5, ["param1"] = 15, ["z"] = 8, ["name"] = "wool:black"}, {["x"] = 4, ["y"] = 5, ["param1"] = 15, ["z"] = 9, ["name"] = "wool:black"}, {["x"] = 4, ["y"] = 5, ["param1"] = 15, ["z"] = 10, ["name"] = "wool:black"}, {["x"] = 4, ["y"] = 5, ["param1"] = 15, ["z"] = 11, ["name"] = "wool:black"}, {["x"] = 4, ["y"] = 5, ["param1"] = 15, ["z"] = 12, ["name"] = "wool:black"}, {["x"] = 4, ["y"] = 5, ["param1"] = 15, ["z"] = 13, ["name"] = "wool:black"}, {["x"] = 4, ["y"] = 5, ["param1"] = 15, ["z"] = 14, ["name"] = "default:steelblock"}, {["x"] = 4, ["y"] = 6, ["param1"] = 15, ["z"] = 1, ["name"] = "default:steelblock"}, {["x"] = 4, ["y"] = 6, ["param1"] = 15, ["z"] = 2, ["name"] = "wool:black"}, {["x"] = 4, ["y"] = 6, ["param1"] = 15, ["z"] = 3, ["name"] = "wool:black"}, {["x"] = 4, ["y"] = 6, ["param1"] = 15, ["z"] = 4, ["name"] = "wool:black"}, {["x"] = 4, ["y"] = 6, ["param1"] = 15, ["z"] = 5, ["name"] = "wool:black"}, {["x"] = 4, ["y"] = 6, ["param1"] = 15, ["z"] = 6, ["name"] = "wool:black"}, {["x"] = 4, ["y"] = 6, ["param1"] = 15, ["z"] = 7, ["name"] = "wool:black"}, {["x"] = 4, ["y"] = 6, ["param1"] = 15, ["z"] = 8, ["name"] = "wool:black"}, {["x"] = 4, ["y"] = 6, ["param1"] = 15, ["z"] = 9, ["name"] = "wool:black"}, {["x"] = 4, ["y"] = 6, ["param1"] = 15, ["z"] = 10, ["name"] = "wool:black"}, {["x"] = 4, ["y"] = 6, ["param1"] = 15, ["z"] = 11, ["name"] = "wool:black"}, {["x"] = 4, ["y"] = 6, ["param1"] = 15, ["z"] = 12, ["name"] = "wool:black"}, {["x"] = 4, ["y"] = 6, ["param1"] = 15, ["z"] = 13, ["name"] = "wool:black"}, {["x"] = 4, ["y"] = 6, ["param1"] = 15, ["z"] = 14, ["name"] = "default:steelblock"}, {["x"] = 4, ["y"] = 7, ["param1"] = 15, ["z"] = 1, ["name"] = "default:steelblock"}, {["x"] = 4, ["y"] = 7, ["param1"] = 15, ["z"] = 2, ["name"] = "wool:black"}, {["x"] = 4, ["y"] = 7, ["param1"] = 15, ["z"] = 3, ["name"] = "wool:black"}, {["x"] = 4, ["y"] = 7, ["param1"] = 15, ["z"] = 4, ["name"] = "wool:black"}, {["x"] = 4, ["y"] = 7, ["param1"] = 15, ["z"] = 5, ["name"] = "wool:black"}, {["x"] = 4, ["y"] = 7, ["param1"] = 15, ["z"] = 6, ["name"] = "wool:black"}, {["x"] = 4, ["y"] = 7, ["param1"] = 15, ["z"] = 7, ["name"] = "wool:black"}, {["x"] = 4, ["y"] = 7, ["param1"] = 15, ["z"] = 8, ["name"] = "wool:black"}, {["x"] = 4, ["y"] = 7, ["param1"] = 15, ["z"] = 9, ["name"] = "wool:black"}, {["x"] = 4, ["y"] = 7, ["param1"] = 15, ["z"] = 10, ["name"] = "wool:black"}, {["x"] = 4, ["y"] = 7, ["param1"] = 15, ["z"] = 11, ["name"] = "wool:black"}, {["x"] = 4, ["y"] = 7, ["param1"] = 15, ["z"] = 12, ["name"] = "wool:black"}, {["x"] = 4, ["y"] = 7, ["param1"] = 15, ["z"] = 13, ["name"] = "wool:black"}, {["x"] = 4, ["y"] = 7, ["param1"] = 15, ["z"] = 14, ["name"] = "default:steelblock"}, {["x"] = 4, ["y"] = 8, ["param1"] = 15, ["z"] = 1, ["name"] = "default:steelblock"}, {["x"] = 4, ["y"] = 8, ["param1"] = 15, ["z"] = 2, ["name"] = "wool:black"}, {["x"] = 4, ["y"] = 8, ["param1"] = 15, ["z"] = 3, ["name"] = "wool:black"}, {["x"] = 4, ["y"] = 8, ["param1"] = 15, ["z"] = 4, ["name"] = "wool:black"}, {["x"] = 4, ["y"] = 8, ["param1"] = 15, ["z"] = 5, ["name"] = "wool:black"}, {["x"] = 4, ["y"] = 8, ["param1"] = 15, ["z"] = 6, ["name"] = "wool:black"}, {["x"] = 4, ["y"] = 8, ["param1"] = 15, ["z"] = 7, ["name"] = "wool:black"}, {["x"] = 4, ["y"] = 8, ["param1"] = 15, ["z"] = 8, ["name"] = "wool:black"}, {["x"] = 4, ["y"] = 8, ["param1"] = 15, ["z"] = 9, ["name"] = "wool:black"}, {["x"] = 4, ["y"] = 8, ["param1"] = 15, ["z"] = 10, ["name"] = "wool:black"}, {["x"] = 4, ["y"] = 8, ["param1"] = 15, ["z"] = 11, ["name"] = "wool:black"}, {["x"] = 4, ["y"] = 8, ["param1"] = 15, ["z"] = 12, ["name"] = "wool:black"}, {["x"] = 4, ["y"] = 8, ["param1"] = 15, ["z"] = 13, ["name"] = "wool:black"}, {["x"] = 4, ["y"] = 8, ["param1"] = 15, ["z"] = 14, ["name"] = "default:steelblock"}, {["x"] = 4, ["y"] = 9, ["param1"] = 15, ["z"] = 1, ["name"] = "default:steelblock"}, {["x"] = 4, ["y"] = 9, ["param1"] = 15, ["z"] = 2, ["name"] = "wool:black"}, {["x"] = 4, ["y"] = 9, ["param1"] = 15, ["z"] = 3, ["name"] = "wool:black"}, {["x"] = 4, ["y"] = 9, ["param1"] = 15, ["z"] = 4, ["name"] = "wool:black"}, {["x"] = 4, ["y"] = 9, ["param1"] = 15, ["z"] = 5, ["name"] = "wool:black"}, {["x"] = 4, ["y"] = 9, ["param1"] = 15, ["z"] = 6, ["name"] = "wool:black"}, {["x"] = 4, ["y"] = 9, ["param1"] = 15, ["z"] = 7, ["name"] = "wool:black"}, {["x"] = 4, ["y"] = 9, ["param1"] = 15, ["z"] = 8, ["name"] = "wool:black"}, {["x"] = 4, ["y"] = 9, ["param1"] = 15, ["z"] = 9, ["name"] = "wool:black"}, {["x"] = 4, ["y"] = 9, ["param1"] = 15, ["z"] = 10, ["name"] = "wool:black"}, {["x"] = 4, ["y"] = 9, ["param1"] = 15, ["z"] = 11, ["name"] = "wool:black"}, {["x"] = 4, ["y"] = 9, ["param1"] = 15, ["z"] = 12, ["name"] = "wool:black"}, {["x"] = 4, ["y"] = 9, ["param1"] = 15, ["z"] = 13, ["name"] = "wool:black"}, {["x"] = 4, ["y"] = 9, ["param1"] = 15, ["z"] = 14, ["name"] = "default:steelblock"}, {["x"] = 4, ["y"] = 10, ["param1"] = 15, ["z"] = 1, ["name"] = "default:steelblock"}, {["x"] = 4, ["y"] = 10, ["param1"] = 15, ["z"] = 2, ["name"] = "wool:black"}, {["x"] = 4, ["y"] = 10, ["param1"] = 15, ["z"] = 3, ["name"] = "wool:black"}, {["x"] = 4, ["y"] = 10, ["param1"] = 15, ["z"] = 4, ["name"] = "wool:black"}, {["x"] = 4, ["y"] = 10, ["param1"] = 15, ["z"] = 5, ["name"] = "wool:black"}, {["x"] = 4, ["y"] = 10, ["param1"] = 15, ["z"] = 6, ["name"] = "wool:black"}, {["x"] = 4, ["y"] = 10, ["param1"] = 15, ["z"] = 7, ["name"] = "wool:black"}, {["x"] = 4, ["y"] = 10, ["param1"] = 15, ["z"] = 8, ["name"] = "wool:black"}, {["x"] = 4, ["y"] = 10, ["param1"] = 15, ["z"] = 9, ["name"] = "wool:black"}, {["x"] = 4, ["y"] = 10, ["param1"] = 15, ["z"] = 10, ["name"] = "wool:black"}, {["x"] = 4, ["y"] = 10, ["param1"] = 15, ["z"] = 11, ["name"] = "wool:black"}, {["x"] = 4, ["y"] = 10, ["param1"] = 15, ["z"] = 12, ["name"] = "wool:black"}, {["x"] = 4, ["y"] = 10, ["param1"] = 15, ["z"] = 13, ["name"] = "wool:black"}, {["x"] = 4, ["y"] = 10, ["param1"] = 15, ["z"] = 14, ["name"] = "default:steelblock"}, {["x"] = 4, ["y"] = 11, ["param1"] = 15, ["z"] = 1, ["name"] = "default:steelblock"}, {["x"] = 4, ["y"] = 11, ["param1"] = 15, ["z"] = 2, ["name"] = "wool:black"}, {["x"] = 4, ["y"] = 11, ["param1"] = 15, ["z"] = 3, ["name"] = "wool:black"}, {["x"] = 4, ["y"] = 11, ["param1"] = 15, ["z"] = 4, ["name"] = "wool:black"}, {["x"] = 4, ["y"] = 11, ["param1"] = 15, ["z"] = 5, ["name"] = "wool:black"}, {["x"] = 4, ["y"] = 11, ["param1"] = 15, ["z"] = 6, ["name"] = "wool:black"}, {["x"] = 4, ["y"] = 11, ["param1"] = 15, ["z"] = 7, ["name"] = "wool:black"}, {["x"] = 4, ["y"] = 11, ["param1"] = 15, ["z"] = 8, ["name"] = "wool:black"}, {["x"] = 4, ["y"] = 11, ["param1"] = 15, ["z"] = 9, ["name"] = "wool:black"}, {["x"] = 4, ["y"] = 11, ["param1"] = 15, ["z"] = 10, ["name"] = "wool:black"}, {["x"] = 4, ["y"] = 11, ["param1"] = 15, ["z"] = 11, ["name"] = "wool:black"}, {["x"] = 4, ["y"] = 11, ["param1"] = 15, ["z"] = 12, ["name"] = "wool:black"}, {["x"] = 4, ["y"] = 11, ["param1"] = 15, ["z"] = 13, ["name"] = "wool:black"}, {["x"] = 4, ["y"] = 11, ["param1"] = 15, ["z"] = 14, ["name"] = "default:steelblock"}, {["x"] = 4, ["y"] = 12, ["param1"] = 15, ["z"] = 2, ["name"] = "wool:black"}, {["x"] = 4, ["y"] = 12, ["param1"] = 15, ["z"] = 3, ["name"] = "wool:black"}, {["x"] = 4, ["y"] = 12, ["param1"] = 15, ["z"] = 4, ["name"] = "wool:black"}, {["x"] = 4, ["y"] = 12, ["param1"] = 15, ["z"] = 5, ["name"] = "wool:black"}, {["x"] = 4, ["y"] = 12, ["param1"] = 15, ["z"] = 6, ["name"] = "wool:black"}, {["x"] = 4, ["y"] = 12, ["param1"] = 15, ["z"] = 7, ["name"] = "wool:black"}, {["x"] = 4, ["y"] = 12, ["param1"] = 15, ["z"] = 8, ["name"] = "wool:black"}, {["x"] = 4, ["y"] = 12, ["param1"] = 15, ["z"] = 9, ["name"] = "wool:black"}, {["x"] = 4, ["y"] = 12, ["param1"] = 15, ["z"] = 10, ["name"] = "wool:black"}, {["x"] = 4, ["y"] = 12, ["param1"] = 15, ["z"] = 11, ["name"] = "wool:black"}, {["x"] = 4, ["y"] = 12, ["param1"] = 15, ["z"] = 12, ["name"] = "wool:black"}, {["x"] = 4, ["y"] = 12, ["param1"] = 15, ["z"] = 13, ["name"] = "wool:black"}, {["x"] = 4, ["y"] = 13, ["param1"] = 15, ["z"] = 2, ["name"] = "wool:black"}, {["x"] = 4, ["y"] = 13, ["param1"] = 15, ["z"] = 3, ["name"] = "wool:black"}, {["x"] = 4, ["y"] = 13, ["param1"] = 15, ["z"] = 4, ["name"] = "wool:black"}, {["x"] = 4, ["y"] = 13, ["param1"] = 15, ["z"] = 5, ["name"] = "wool:black"}, {["x"] = 4, ["y"] = 13, ["param1"] = 15, ["z"] = 6, ["name"] = "wool:black"}, {["x"] = 4, ["y"] = 13, ["param1"] = 15, ["z"] = 7, ["name"] = "wool:black"}, {["x"] = 4, ["y"] = 13, ["param1"] = 15, ["z"] = 8, ["name"] = "wool:black"}, {["x"] = 4, ["y"] = 13, ["param1"] = 15, ["z"] = 9, ["name"] = "wool:black"}, {["x"] = 4, ["y"] = 13, ["param1"] = 15, ["z"] = 10, ["name"] = "wool:black"}, {["x"] = 4, ["y"] = 13, ["param1"] = 15, ["z"] = 11, ["name"] = "wool:black"}, {["x"] = 4, ["y"] = 13, ["param1"] = 15, ["z"] = 12, ["name"] = "wool:black"}, {["x"] = 4, ["y"] = 13, ["param1"] = 15, ["z"] = 13, ["name"] = "wool:black"}, {["x"] = 4, ["y"] = 14, ["z"] = 1, ["name"] = "wool:black"}, {["x"] = 4, ["y"] = 14, ["param1"] = 15, ["z"] = 2, ["name"] = "wool:black"}, {["x"] = 4, ["y"] = 14, ["param1"] = 15, ["z"] = 3, ["name"] = "wool:black"}, {["x"] = 4, ["y"] = 14, ["param1"] = 15, ["z"] = 4, ["name"] = "wool:black"}, {["x"] = 4, ["y"] = 14, ["param1"] = 15, ["z"] = 5, ["name"] = "wool:black"}, {["x"] = 4, ["y"] = 14, ["param1"] = 15, ["z"] = 6, ["name"] = "wool:black"}, {["x"] = 4, ["y"] = 14, ["param1"] = 15, ["z"] = 7, ["name"] = "wool:black"}, {["x"] = 4, ["y"] = 14, ["param1"] = 15, ["z"] = 8, ["name"] = "wool:black"}, {["x"] = 4, ["y"] = 14, ["param1"] = 15, ["z"] = 9, ["name"] = "wool:black"}, {["x"] = 4, ["y"] = 14, ["param1"] = 15, ["z"] = 10, ["name"] = "wool:black"}, {["x"] = 4, ["y"] = 14, ["param1"] = 15, ["z"] = 11, ["name"] = "wool:black"}, {["x"] = 4, ["y"] = 14, ["param1"] = 15, ["z"] = 12, ["name"] = "wool:black"}, {["x"] = 4, ["y"] = 14, ["param1"] = 15, ["z"] = 13, ["name"] = "wool:black"}, {["x"] = 4, ["y"] = 14, ["z"] = 14, ["name"] = "wool:black"}, {["x"] = 4, ["y"] = 15, ["z"] = 1, ["name"] = "wool:black"}, {["x"] = 4, ["y"] = 15, ["param1"] = 14, ["z"] = 2, ["name"] = "wool:black"}, {["x"] = 4, ["y"] = 15, ["param1"] = 14, ["z"] = 3, ["name"] = "wool:black"}, {["x"] = 4, ["y"] = 15, ["param1"] = 14, ["z"] = 4, ["name"] = "wool:black"}, {["x"] = 4, ["y"] = 15, ["param1"] = 14, ["z"] = 5, ["name"] = "wool:black"}, {["x"] = 4, ["y"] = 15, ["param1"] = 14, ["z"] = 6, ["name"] = "wool:black"}, {["x"] = 4, ["y"] = 15, ["param1"] = 14, ["z"] = 7, ["name"] = "wool:black"}, {["x"] = 4, ["y"] = 15, ["param1"] = 14, ["z"] = 8, ["name"] = "wool:black"}, {["x"] = 4, ["y"] = 15, ["param1"] = 14, ["z"] = 9, ["name"] = "wool:black"}, {["x"] = 4, ["y"] = 15, ["param1"] = 14, ["z"] = 10, ["name"] = "wool:black"}, {["x"] = 4, ["y"] = 15, ["param1"] = 14, ["z"] = 11, ["name"] = "wool:black"}, {["x"] = 4, ["y"] = 15, ["param1"] = 14, ["z"] = 12, ["name"] = "wool:black"}, {["x"] = 4, ["y"] = 15, ["param1"] = 14, ["z"] = 13, ["name"] = "wool:black"}, {["x"] = 4, ["y"] = 15, ["z"] = 14, ["name"] = "wool:black"}, {["x"] = 5, ["y"] = 0, ["z"] = 2, ["name"] = "wool:black"}, {["x"] = 5, ["y"] = 0, ["param1"] = 15, ["z"] = 3, ["name"] = "wool:black"}, {["x"] = 5, ["y"] = 0, ["param1"] = 15, ["z"] = 4, ["name"] = "wool:black"}, {["x"] = 5, ["y"] = 0, ["param1"] = 15, ["z"] = 5, ["name"] = "wool:black"}, {["x"] = 5, ["y"] = 0, ["param1"] = 15, ["z"] = 6, ["name"] = "wool:black"}, {["x"] = 5, ["y"] = 0, ["param1"] = 15, ["z"] = 7, ["name"] = "wool:black"}, {["x"] = 5, ["y"] = 0, ["param1"] = 15, ["z"] = 8, ["name"] = "wool:black"}, {["x"] = 5, ["y"] = 0, ["param1"] = 15, ["z"] = 9, ["name"] = "wool:black"}, {["x"] = 5, ["y"] = 0, ["param1"] = 15, ["z"] = 10, ["name"] = "wool:black"}, {["x"] = 5, ["y"] = 0, ["param1"] = 14, ["z"] = 11, ["name"] = "wool:black"}, {["x"] = 5, ["y"] = 0, ["param1"] = 14, ["z"] = 12, ["name"] = "wool:black"}, {["x"] = 5, ["y"] = 0, ["param1"] = 14, ["z"] = 13, ["name"] = "wool:black"}, {["x"] = 5, ["y"] = 1, ["z"] = 2, ["name"] = "wool:black"}, {["x"] = 5, ["y"] = 1, ["param1"] = 15, ["z"] = 3, ["name"] = "wool:black"}, {["x"] = 5, ["y"] = 1, ["param1"] = 15, ["z"] = 4, ["name"] = "wool:black"}, {["x"] = 5, ["y"] = 1, ["param1"] = 15, ["z"] = 5, ["name"] = "wool:black"}, {["x"] = 5, ["y"] = 1, ["param1"] = 15, ["z"] = 6, ["name"] = "wool:black"}, {["x"] = 5, ["y"] = 1, ["param1"] = 15, ["z"] = 7, ["name"] = "wool:black"}, {["x"] = 5, ["y"] = 1, ["param1"] = 15, ["z"] = 8, ["name"] = "wool:black"}, {["x"] = 5, ["y"] = 1, ["param1"] = 15, ["z"] = 9, ["name"] = "wool:black"}, {["x"] = 5, ["y"] = 1, ["param1"] = 15, ["z"] = 10, ["name"] = "wool:black"}, {["x"] = 5, ["y"] = 1, ["param1"] = 15, ["z"] = 11, ["name"] = "wool:black"}, {["x"] = 5, ["y"] = 1, ["param1"] = 15, ["z"] = 12, ["name"] = "wool:black"}, {["x"] = 5, ["y"] = 1, ["param1"] = 15, ["z"] = 13, ["name"] = "wool:black"}, {["x"] = 5, ["y"] = 2, ["param1"] = 15, ["z"] = 1, ["name"] = "default:steelblock"}, {["x"] = 5, ["y"] = 2, ["param1"] = 15, ["z"] = 2, ["name"] = "wool:black"}, {["x"] = 5, ["y"] = 2, ["param1"] = 15, ["z"] = 3, ["name"] = "wool:black"}, {["x"] = 5, ["y"] = 2, ["param1"] = 15, ["z"] = 4, ["name"] = "wool:black"}, {["x"] = 5, ["y"] = 2, ["param1"] = 15, ["z"] = 5, ["name"] = "wool:black"}, {["x"] = 5, ["y"] = 2, ["param1"] = 15, ["z"] = 6, ["name"] = "wool:black"}, {["x"] = 5, ["y"] = 2, ["param1"] = 15, ["z"] = 7, ["name"] = "wool:black"}, {["x"] = 5, ["y"] = 2, ["param1"] = 15, ["z"] = 8, ["name"] = "wool:black"}, {["x"] = 5, ["y"] = 2, ["param1"] = 15, ["z"] = 9, ["name"] = "wool:black"}, {["x"] = 5, ["y"] = 2, ["param1"] = 15, ["z"] = 10, ["name"] = "wool:black"}, {["x"] = 5, ["y"] = 2, ["param1"] = 15, ["z"] = 11, ["name"] = "wool:black"}, {["x"] = 5, ["y"] = 2, ["param1"] = 15, ["z"] = 12, ["name"] = "wool:black"}, {["x"] = 5, ["y"] = 2, ["param1"] = 15, ["z"] = 13, ["name"] = "wool:black"}, {["x"] = 5, ["y"] = 2, ["param1"] = 15, ["z"] = 14, ["name"] = "default:steelblock"}, {["x"] = 5, ["y"] = 3, ["param1"] = 15, ["z"] = 1, ["name"] = "default:steelblock"}, {["x"] = 5, ["y"] = 3, ["param1"] = 15, ["z"] = 2, ["name"] = "wool:black"}, {["x"] = 5, ["y"] = 3, ["param1"] = 15, ["z"] = 3, ["name"] = "wool:black"}, {["x"] = 5, ["y"] = 3, ["param1"] = 15, ["z"] = 4, ["name"] = "wool:black"}, {["x"] = 5, ["y"] = 3, ["param1"] = 15, ["z"] = 5, ["name"] = "wool:black"}, {["x"] = 5, ["y"] = 3, ["param1"] = 15, ["z"] = 6, ["name"] = "wool:black"}, {["x"] = 5, ["y"] = 3, ["param1"] = 15, ["z"] = 7, ["name"] = "wool:black"}, {["x"] = 5, ["y"] = 3, ["param1"] = 15, ["z"] = 8, ["name"] = "wool:black"}, {["x"] = 5, ["y"] = 3, ["param1"] = 15, ["z"] = 9, ["name"] = "wool:black"}, {["x"] = 5, ["y"] = 3, ["param1"] = 15, ["z"] = 10, ["name"] = "wool:black"}, {["x"] = 5, ["y"] = 3, ["param1"] = 15, ["z"] = 11, ["name"] = "wool:black"}, {["x"] = 5, ["y"] = 3, ["param1"] = 15, ["z"] = 12, ["name"] = "wool:black"}, {["x"] = 5, ["y"] = 3, ["param1"] = 15, ["z"] = 13, ["name"] = "wool:black"}, {["x"] = 5, ["y"] = 3, ["param1"] = 15, ["z"] = 14, ["name"] = "default:steelblock"}, {["x"] = 5, ["y"] = 4, ["param1"] = 15, ["z"] = 1, ["name"] = "default:steelblock"}, {["x"] = 5, ["y"] = 4, ["param1"] = 15, ["z"] = 2, ["name"] = "wool:black"}, {["x"] = 5, ["y"] = 4, ["param1"] = 15, ["z"] = 3, ["name"] = "wool:black"}, {["x"] = 5, ["y"] = 4, ["param1"] = 15, ["z"] = 4, ["name"] = "wool:black"}, {["x"] = 5, ["y"] = 4, ["param1"] = 15, ["z"] = 5, ["name"] = "wool:black"}, {["x"] = 5, ["y"] = 4, ["param1"] = 15, ["z"] = 6, ["name"] = "wool:black"}, {["x"] = 5, ["y"] = 4, ["param1"] = 15, ["z"] = 7, ["name"] = "wool:black"}, {["x"] = 5, ["y"] = 4, ["param1"] = 15, ["z"] = 8, ["name"] = "wool:black"}, {["x"] = 5, ["y"] = 4, ["param1"] = 15, ["z"] = 9, ["name"] = "wool:black"}, {["x"] = 5, ["y"] = 4, ["param1"] = 15, ["z"] = 10, ["name"] = "wool:black"}, {["x"] = 5, ["y"] = 4, ["param1"] = 15, ["z"] = 11, ["name"] = "wool:black"}, {["x"] = 5, ["y"] = 4, ["param1"] = 15, ["z"] = 12, ["name"] = "wool:black"}, {["x"] = 5, ["y"] = 4, ["param1"] = 15, ["z"] = 13, ["name"] = "wool:black"}, {["x"] = 5, ["y"] = 4, ["param1"] = 15, ["z"] = 14, ["name"] = "default:steelblock"}, {["x"] = 5, ["y"] = 5, ["param1"] = 15, ["z"] = 1, ["name"] = "default:steelblock"}, {["x"] = 5, ["y"] = 5, ["param1"] = 15, ["z"] = 2, ["name"] = "wool:black"}, {["x"] = 5, ["y"] = 5, ["param1"] = 15, ["z"] = 3, ["name"] = "wool:black"}, {["x"] = 5, ["y"] = 5, ["param1"] = 15, ["z"] = 4, ["name"] = "wool:black"}, {["x"] = 5, ["y"] = 5, ["param1"] = 15, ["z"] = 5, ["name"] = "wool:black"}, {["x"] = 5, ["y"] = 5, ["param1"] = 15, ["z"] = 6, ["name"] = "wool:black"}, {["x"] = 5, ["y"] = 5, ["param1"] = 15, ["z"] = 7, ["name"] = "wool:black"}, {["x"] = 5, ["y"] = 5, ["param1"] = 15, ["z"] = 8, ["name"] = "wool:black"}, {["x"] = 5, ["y"] = 5, ["param1"] = 15, ["z"] = 9, ["name"] = "wool:black"}, {["x"] = 5, ["y"] = 5, ["param1"] = 15, ["z"] = 10, ["name"] = "wool:black"}, {["x"] = 5, ["y"] = 5, ["param1"] = 15, ["z"] = 11, ["name"] = "wool:black"}, {["x"] = 5, ["y"] = 5, ["param1"] = 15, ["z"] = 12, ["name"] = "wool:black"}, {["x"] = 5, ["y"] = 5, ["param1"] = 15, ["z"] = 13, ["name"] = "wool:black"}, {["x"] = 5, ["y"] = 5, ["param1"] = 15, ["z"] = 14, ["name"] = "default:steelblock"}, {["x"] = 5, ["y"] = 6, ["param1"] = 15, ["z"] = 1, ["name"] = "default:steelblock"}, {["x"] = 5, ["y"] = 6, ["param1"] = 15, ["z"] = 2, ["name"] = "wool:black"}, {["x"] = 5, ["y"] = 6, ["param1"] = 15, ["z"] = 3, ["name"] = "wool:black"}, {["x"] = 5, ["y"] = 6, ["param1"] = 15, ["z"] = 4, ["name"] = "wool:black"}, {["x"] = 5, ["y"] = 6, ["param1"] = 15, ["z"] = 5, ["name"] = "wool:black"}, {["x"] = 5, ["y"] = 6, ["param1"] = 15, ["z"] = 6, ["name"] = "wool:black"}, {["x"] = 5, ["y"] = 6, ["param1"] = 15, ["z"] = 7, ["name"] = "wool:black"}, {["x"] = 5, ["y"] = 6, ["param1"] = 15, ["z"] = 8, ["name"] = "wool:black"}, {["x"] = 5, ["y"] = 6, ["param1"] = 15, ["z"] = 9, ["name"] = "wool:black"}, {["x"] = 5, ["y"] = 6, ["param1"] = 15, ["z"] = 10, ["name"] = "wool:black"}, {["x"] = 5, ["y"] = 6, ["param1"] = 15, ["z"] = 11, ["name"] = "wool:black"}, {["x"] = 5, ["y"] = 6, ["param1"] = 15, ["z"] = 12, ["name"] = "wool:black"}, {["x"] = 5, ["y"] = 6, ["param1"] = 15, ["z"] = 13, ["name"] = "wool:black"}, {["x"] = 5, ["y"] = 6, ["param1"] = 15, ["z"] = 14, ["name"] = "default:steelblock"}, {["x"] = 5, ["y"] = 7, ["param1"] = 15, ["z"] = 1, ["name"] = "default:steelblock"}, {["x"] = 5, ["y"] = 7, ["param1"] = 15, ["z"] = 2, ["name"] = "wool:black"}, {["x"] = 5, ["y"] = 7, ["param1"] = 15, ["z"] = 3, ["name"] = "wool:black"}, {["x"] = 5, ["y"] = 7, ["param1"] = 15, ["z"] = 4, ["name"] = "wool:black"}, {["x"] = 5, ["y"] = 7, ["param1"] = 15, ["z"] = 5, ["name"] = "wool:black"}, {["x"] = 5, ["y"] = 7, ["param1"] = 15, ["z"] = 6, ["name"] = "wool:black"}, {["x"] = 5, ["y"] = 7, ["param1"] = 15, ["z"] = 7, ["name"] = "wool:black"}, {["x"] = 5, ["y"] = 7, ["param1"] = 15, ["z"] = 8, ["name"] = "wool:black"}, {["x"] = 5, ["y"] = 7, ["param1"] = 15, ["z"] = 9, ["name"] = "wool:black"}, {["x"] = 5, ["y"] = 7, ["param1"] = 15, ["z"] = 10, ["name"] = "wool:black"}, {["x"] = 5, ["y"] = 7, ["param1"] = 15, ["z"] = 11, ["name"] = "wool:black"}, {["x"] = 5, ["y"] = 7, ["param1"] = 15, ["z"] = 12, ["name"] = "wool:black"}, {["x"] = 5, ["y"] = 7, ["param1"] = 15, ["z"] = 13, ["name"] = "wool:black"}, {["x"] = 5, ["y"] = 7, ["param1"] = 15, ["z"] = 14, ["name"] = "default:steelblock"}, {["x"] = 5, ["y"] = 8, ["param1"] = 15, ["z"] = 1, ["name"] = "default:steelblock"}, {["x"] = 5, ["y"] = 8, ["param1"] = 15, ["z"] = 2, ["name"] = "wool:black"}, {["x"] = 5, ["y"] = 8, ["param1"] = 15, ["z"] = 3, ["name"] = "wool:black"}, {["x"] = 5, ["y"] = 8, ["param1"] = 15, ["z"] = 4, ["name"] = "wool:black"}, {["x"] = 5, ["y"] = 8, ["param1"] = 15, ["z"] = 5, ["name"] = "wool:black"}, {["x"] = 5, ["y"] = 8, ["param1"] = 15, ["z"] = 6, ["name"] = "wool:black"}, {["x"] = 5, ["y"] = 8, ["param1"] = 15, ["z"] = 7, ["name"] = "wool:black"}, {["x"] = 5, ["y"] = 8, ["param1"] = 15, ["z"] = 8, ["name"] = "wool:black"}, {["x"] = 5, ["y"] = 8, ["param1"] = 15, ["z"] = 9, ["name"] = "wool:black"}, {["x"] = 5, ["y"] = 8, ["param1"] = 15, ["z"] = 10, ["name"] = "wool:black"}, {["x"] = 5, ["y"] = 8, ["param1"] = 15, ["z"] = 11, ["name"] = "wool:black"}, {["x"] = 5, ["y"] = 8, ["param1"] = 15, ["z"] = 12, ["name"] = "wool:black"}, {["x"] = 5, ["y"] = 8, ["param1"] = 15, ["z"] = 13, ["name"] = "wool:black"}, {["x"] = 5, ["y"] = 8, ["param1"] = 15, ["z"] = 14, ["name"] = "default:steelblock"}, {["x"] = 5, ["y"] = 9, ["param1"] = 15, ["z"] = 1, ["name"] = "default:steelblock"}, {["x"] = 5, ["y"] = 9, ["param1"] = 15, ["z"] = 2, ["name"] = "wool:black"}, {["x"] = 5, ["y"] = 9, ["param1"] = 15, ["z"] = 3, ["name"] = "wool:black"}, {["x"] = 5, ["y"] = 9, ["param1"] = 15, ["z"] = 4, ["name"] = "wool:black"}, {["x"] = 5, ["y"] = 9, ["param1"] = 15, ["z"] = 5, ["name"] = "wool:black"}, {["x"] = 5, ["y"] = 9, ["param1"] = 15, ["z"] = 6, ["name"] = "wool:black"}, {["x"] = 5, ["y"] = 9, ["param1"] = 15, ["z"] = 7, ["name"] = "wool:black"}, {["x"] = 5, ["y"] = 9, ["param1"] = 15, ["z"] = 8, ["name"] = "wool:black"}, {["x"] = 5, ["y"] = 9, ["param1"] = 15, ["z"] = 9, ["name"] = "wool:black"}, {["x"] = 5, ["y"] = 9, ["param1"] = 15, ["z"] = 10, ["name"] = "wool:black"}, {["x"] = 5, ["y"] = 9, ["param1"] = 15, ["z"] = 11, ["name"] = "wool:black"}, {["x"] = 5, ["y"] = 9, ["param1"] = 15, ["z"] = 12, ["name"] = "wool:black"}, {["x"] = 5, ["y"] = 9, ["param1"] = 15, ["z"] = 13, ["name"] = "wool:black"}, {["x"] = 5, ["y"] = 9, ["param1"] = 15, ["z"] = 14, ["name"] = "default:steelblock"}, {["x"] = 5, ["y"] = 10, ["param1"] = 15, ["z"] = 1, ["name"] = "default:steelblock"}, {["x"] = 5, ["y"] = 10, ["param1"] = 15, ["z"] = 2, ["name"] = "wool:black"}, {["x"] = 5, ["y"] = 10, ["param1"] = 15, ["z"] = 3, ["name"] = "wool:black"}, {["x"] = 5, ["y"] = 10, ["param1"] = 15, ["z"] = 4, ["name"] = "wool:black"}, {["x"] = 5, ["y"] = 10, ["param1"] = 15, ["z"] = 5, ["name"] = "wool:black"}, {["x"] = 5, ["y"] = 10, ["param1"] = 15, ["z"] = 6, ["name"] = "wool:black"}, {["x"] = 5, ["y"] = 10, ["param1"] = 15, ["z"] = 7, ["name"] = "wool:black"}, {["x"] = 5, ["y"] = 10, ["param1"] = 15, ["z"] = 8, ["name"] = "wool:black"}, {["x"] = 5, ["y"] = 10, ["param1"] = 15, ["z"] = 9, ["name"] = "wool:black"}, {["x"] = 5, ["y"] = 10, ["param1"] = 15, ["z"] = 10, ["name"] = "wool:black"}, {["x"] = 5, ["y"] = 10, ["param1"] = 15, ["z"] = 11, ["name"] = "wool:black"}, {["x"] = 5, ["y"] = 10, ["param1"] = 15, ["z"] = 12, ["name"] = "wool:black"}, {["x"] = 5, ["y"] = 10, ["param1"] = 15, ["z"] = 13, ["name"] = "wool:black"}, {["x"] = 5, ["y"] = 10, ["param1"] = 15, ["z"] = 14, ["name"] = "default:steelblock"}, {["x"] = 5, ["y"] = 11, ["param1"] = 15, ["z"] = 1, ["name"] = "default:steelblock"}, {["x"] = 5, ["y"] = 11, ["param1"] = 15, ["z"] = 2, ["name"] = "wool:black"}, {["x"] = 5, ["y"] = 11, ["param1"] = 15, ["z"] = 3, ["name"] = "wool:black"}, {["x"] = 5, ["y"] = 11, ["param1"] = 15, ["z"] = 4, ["name"] = "wool:black"}, {["x"] = 5, ["y"] = 11, ["param1"] = 15, ["z"] = 5, ["name"] = "wool:black"}, {["x"] = 5, ["y"] = 11, ["param1"] = 15, ["z"] = 6, ["name"] = "wool:black"}, {["x"] = 5, ["y"] = 11, ["param1"] = 15, ["z"] = 7, ["name"] = "wool:black"}, {["x"] = 5, ["y"] = 11, ["param1"] = 15, ["z"] = 8, ["name"] = "wool:black"}, {["x"] = 5, ["y"] = 11, ["param1"] = 15, ["z"] = 9, ["name"] = "wool:black"}, {["x"] = 5, ["y"] = 11, ["param1"] = 15, ["z"] = 10, ["name"] = "wool:black"}, {["x"] = 5, ["y"] = 11, ["param1"] = 15, ["z"] = 11, ["name"] = "wool:black"}, {["x"] = 5, ["y"] = 11, ["param1"] = 15, ["z"] = 12, ["name"] = "wool:black"}, {["x"] = 5, ["y"] = 11, ["param1"] = 15, ["z"] = 13, ["name"] = "wool:black"}, {["x"] = 5, ["y"] = 11, ["param1"] = 15, ["z"] = 14, ["name"] = "default:steelblock"}, {["x"] = 5, ["y"] = 12, ["param1"] = 15, ["z"] = 2, ["name"] = "wool:black"}, {["x"] = 5, ["y"] = 12, ["param1"] = 15, ["z"] = 3, ["name"] = "wool:black"}, {["x"] = 5, ["y"] = 12, ["param1"] = 15, ["z"] = 4, ["name"] = "wool:black"}, {["x"] = 5, ["y"] = 12, ["param1"] = 15, ["z"] = 5, ["name"] = "wool:black"}, {["x"] = 5, ["y"] = 12, ["param1"] = 15, ["z"] = 6, ["name"] = "wool:black"}, {["x"] = 5, ["y"] = 12, ["param1"] = 15, ["z"] = 7, ["name"] = "wool:black"}, {["x"] = 5, ["y"] = 12, ["param1"] = 15, ["z"] = 8, ["name"] = "wool:black"}, {["x"] = 5, ["y"] = 12, ["param1"] = 15, ["z"] = 9, ["name"] = "wool:black"}, {["x"] = 5, ["y"] = 12, ["param1"] = 15, ["z"] = 10, ["name"] = "wool:black"}, {["x"] = 5, ["y"] = 12, ["param1"] = 15, ["z"] = 11, ["name"] = "wool:black"}, {["x"] = 5, ["y"] = 12, ["param1"] = 15, ["z"] = 12, ["name"] = "wool:black"}, {["x"] = 5, ["y"] = 12, ["param1"] = 15, ["z"] = 13, ["name"] = "wool:black"}, {["x"] = 5, ["y"] = 13, ["param1"] = 15, ["z"] = 2, ["name"] = "wool:black"}, {["x"] = 5, ["y"] = 13, ["param1"] = 15, ["z"] = 3, ["name"] = "wool:black"}, {["x"] = 5, ["y"] = 13, ["param1"] = 15, ["z"] = 4, ["name"] = "wool:black"}, {["x"] = 5, ["y"] = 13, ["param1"] = 15, ["z"] = 5, ["name"] = "wool:black"}, {["x"] = 5, ["y"] = 13, ["param1"] = 15, ["z"] = 6, ["name"] = "wool:black"}, {["x"] = 5, ["y"] = 13, ["param1"] = 15, ["z"] = 7, ["name"] = "wool:black"}, {["x"] = 5, ["y"] = 13, ["param1"] = 15, ["z"] = 8, ["name"] = "wool:black"}, {["x"] = 5, ["y"] = 13, ["param1"] = 15, ["z"] = 9, ["name"] = "wool:black"}, {["x"] = 5, ["y"] = 13, ["param1"] = 15, ["z"] = 10, ["name"] = "wool:black"}, {["x"] = 5, ["y"] = 13, ["param1"] = 15, ["z"] = 11, ["name"] = "wool:black"}, {["x"] = 5, ["y"] = 13, ["param1"] = 15, ["z"] = 12, ["name"] = "wool:black"}, {["x"] = 5, ["y"] = 13, ["param1"] = 15, ["z"] = 13, ["name"] = "wool:black"}, {["x"] = 5, ["y"] = 14, ["z"] = 1, ["name"] = "wool:black"}, {["x"] = 5, ["y"] = 14, ["param1"] = 15, ["z"] = 2, ["name"] = "wool:black"}, {["x"] = 5, ["y"] = 14, ["param1"] = 15, ["z"] = 3, ["name"] = "wool:black"}, {["x"] = 5, ["y"] = 14, ["param1"] = 15, ["z"] = 4, ["name"] = "wool:black"}, {["x"] = 5, ["y"] = 14, ["param1"] = 15, ["z"] = 5, ["name"] = "wool:black"}, {["x"] = 5, ["y"] = 14, ["param1"] = 15, ["z"] = 6, ["name"] = "wool:black"}, {["x"] = 5, ["y"] = 14, ["param1"] = 15, ["z"] = 7, ["name"] = "wool:black"}, {["x"] = 5, ["y"] = 14, ["param1"] = 15, ["z"] = 8, ["name"] = "wool:black"}, {["x"] = 5, ["y"] = 14, ["param1"] = 15, ["z"] = 9, ["name"] = "wool:black"}, {["x"] = 5, ["y"] = 14, ["param1"] = 15, ["z"] = 10, ["name"] = "wool:black"}, {["x"] = 5, ["y"] = 14, ["param1"] = 15, ["z"] = 11, ["name"] = "wool:black"}, {["x"] = 5, ["y"] = 14, ["param1"] = 15, ["z"] = 12, ["name"] = "wool:black"}, {["x"] = 5, ["y"] = 14, ["param1"] = 15, ["z"] = 13, ["name"] = "wool:black"}, {["x"] = 5, ["y"] = 14, ["z"] = 14, ["name"] = "wool:black"}, {["x"] = 5, ["y"] = 15, ["z"] = 1, ["name"] = "wool:black"}, {["x"] = 5, ["y"] = 15, ["param1"] = 14, ["z"] = 2, ["name"] = "wool:black"}, {["x"] = 5, ["y"] = 15, ["param1"] = 14, ["z"] = 3, ["name"] = "wool:black"}, {["x"] = 5, ["y"] = 15, ["param1"] = 14, ["z"] = 4, ["name"] = "wool:black"}, {["x"] = 5, ["y"] = 15, ["param1"] = 14, ["z"] = 5, ["name"] = "wool:black"}, {["x"] = 5, ["y"] = 15, ["param1"] = 14, ["z"] = 6, ["name"] = "wool:black"}, {["x"] = 5, ["y"] = 15, ["param1"] = 14, ["z"] = 7, ["name"] = "wool:black"}, {["x"] = 5, ["y"] = 15, ["param1"] = 14, ["z"] = 8, ["name"] = "wool:black"}, {["x"] = 5, ["y"] = 15, ["param1"] = 14, ["z"] = 9, ["name"] = "wool:black"}, {["x"] = 5, ["y"] = 15, ["param1"] = 14, ["z"] = 10, ["name"] = "wool:black"}, {["x"] = 5, ["y"] = 15, ["param1"] = 14, ["z"] = 11, ["name"] = "wool:black"}, {["x"] = 5, ["y"] = 15, ["param1"] = 14, ["z"] = 12, ["name"] = "wool:black"}, {["x"] = 5, ["y"] = 15, ["param1"] = 14, ["z"] = 13, ["name"] = "wool:black"}, {["x"] = 5, ["y"] = 15, ["z"] = 14, ["name"] = "wool:black"}, {["x"] = 6, ["y"] = 0, ["z"] = 2, ["name"] = "wool:black"}, {["x"] = 6, ["y"] = 0, ["param1"] = 15, ["z"] = 3, ["name"] = "wool:black"}, {["x"] = 6, ["y"] = 0, ["param1"] = 15, ["z"] = 4, ["name"] = "wool:black"}, {["x"] = 6, ["y"] = 0, ["param1"] = 15, ["z"] = 5, ["name"] = "wool:black"}, {["x"] = 6, ["y"] = 0, ["param1"] = 15, ["z"] = 6, ["name"] = "wool:black"}, {["x"] = 6, ["y"] = 0, ["param1"] = 15, ["z"] = 7, ["name"] = "wool:black"}, {["x"] = 6, ["y"] = 0, ["param1"] = 15, ["z"] = 8, ["name"] = "wool:black"}, {["x"] = 6, ["y"] = 0, ["param1"] = 15, ["z"] = 9, ["name"] = "wool:black"}, {["x"] = 6, ["y"] = 0, ["param1"] = 15, ["z"] = 10, ["name"] = "wool:black"}, {["x"] = 6, ["y"] = 0, ["param1"] = 14, ["z"] = 11, ["name"] = "wool:black"}, {["x"] = 6, ["y"] = 0, ["param1"] = 14, ["z"] = 12, ["name"] = "wool:black"}, {["x"] = 6, ["y"] = 0, ["param1"] = 14, ["z"] = 13, ["name"] = "wool:black"}, {["x"] = 6, ["y"] = 1, ["z"] = 2, ["name"] = "wool:black"}, {["x"] = 6, ["y"] = 1, ["param1"] = 15, ["z"] = 3, ["name"] = "wool:black"}, {["x"] = 6, ["y"] = 1, ["param1"] = 15, ["z"] = 4, ["name"] = "wool:black"}, {["x"] = 6, ["y"] = 1, ["param1"] = 15, ["z"] = 5, ["name"] = "wool:black"}, {["x"] = 6, ["y"] = 1, ["param1"] = 15, ["z"] = 6, ["name"] = "wool:black"}, {["x"] = 6, ["y"] = 1, ["param1"] = 15, ["z"] = 7, ["name"] = "wool:black"}, {["x"] = 6, ["y"] = 1, ["param1"] = 15, ["z"] = 8, ["name"] = "wool:black"}, {["x"] = 6, ["y"] = 1, ["param1"] = 15, ["z"] = 9, ["name"] = "wool:black"}, {["x"] = 6, ["y"] = 1, ["param1"] = 15, ["z"] = 10, ["name"] = "wool:black"}, {["x"] = 6, ["y"] = 1, ["param1"] = 15, ["z"] = 11, ["name"] = "wool:black"}, {["x"] = 6, ["y"] = 1, ["param1"] = 15, ["z"] = 12, ["name"] = "wool:black"}, {["x"] = 6, ["y"] = 1, ["param1"] = 15, ["z"] = 13, ["name"] = "wool:black"}, {["x"] = 6, ["y"] = 2, ["param1"] = 15, ["z"] = 1, ["name"] = "default:steelblock"}, {["x"] = 6, ["y"] = 2, ["param1"] = 15, ["z"] = 2, ["name"] = "wool:black"}, {["x"] = 6, ["y"] = 2, ["param1"] = 15, ["z"] = 3, ["name"] = "wool:black"}, {["x"] = 6, ["y"] = 2, ["param1"] = 15, ["z"] = 4, ["name"] = "wool:black"}, {["x"] = 6, ["y"] = 2, ["param1"] = 15, ["z"] = 5, ["name"] = "wool:black"}, {["x"] = 6, ["y"] = 2, ["param1"] = 15, ["z"] = 6, ["name"] = "wool:black"}, {["x"] = 6, ["y"] = 2, ["param1"] = 15, ["z"] = 7, ["name"] = "wool:black"}, {["x"] = 6, ["y"] = 2, ["param1"] = 15, ["z"] = 8, ["name"] = "wool:black"}, {["x"] = 6, ["y"] = 2, ["param1"] = 15, ["z"] = 9, ["name"] = "wool:black"}, {["x"] = 6, ["y"] = 2, ["param1"] = 15, ["z"] = 10, ["name"] = "wool:black"}, {["x"] = 6, ["y"] = 2, ["param1"] = 15, ["z"] = 11, ["name"] = "wool:black"}, {["x"] = 6, ["y"] = 2, ["param1"] = 15, ["z"] = 12, ["name"] = "wool:black"}, {["x"] = 6, ["y"] = 2, ["param1"] = 15, ["z"] = 13, ["name"] = "wool:black"}, {["x"] = 6, ["y"] = 2, ["param1"] = 15, ["z"] = 14, ["name"] = "default:steelblock"}, {["x"] = 6, ["y"] = 3, ["param1"] = 15, ["z"] = 1, ["name"] = "default:steelblock"}, {["x"] = 6, ["y"] = 3, ["param1"] = 15, ["z"] = 2, ["name"] = "wool:black"}, {["x"] = 6, ["y"] = 3, ["param1"] = 15, ["z"] = 3, ["name"] = "wool:black"}, {["x"] = 6, ["y"] = 3, ["param1"] = 15, ["z"] = 4, ["name"] = "wool:black"}, {["x"] = 6, ["y"] = 3, ["param1"] = 15, ["z"] = 5, ["name"] = "wool:black"}, {["x"] = 6, ["y"] = 3, ["param1"] = 15, ["z"] = 6, ["name"] = "wool:black"}, {["x"] = 6, ["y"] = 3, ["param1"] = 15, ["z"] = 7, ["name"] = "wool:black"}, {["x"] = 6, ["y"] = 3, ["param1"] = 15, ["z"] = 8, ["name"] = "wool:black"}, {["x"] = 6, ["y"] = 3, ["param1"] = 15, ["z"] = 9, ["name"] = "wool:black"}, {["x"] = 6, ["y"] = 3, ["param1"] = 15, ["z"] = 10, ["name"] = "wool:black"}, {["x"] = 6, ["y"] = 3, ["param1"] = 15, ["z"] = 11, ["name"] = "wool:black"}, {["x"] = 6, ["y"] = 3, ["param1"] = 15, ["z"] = 12, ["name"] = "wool:black"}, {["x"] = 6, ["y"] = 3, ["param1"] = 15, ["z"] = 13, ["name"] = "wool:black"}, {["x"] = 6, ["y"] = 3, ["param1"] = 15, ["z"] = 14, ["name"] = "default:steelblock"}, {["x"] = 6, ["y"] = 4, ["param1"] = 15, ["z"] = 1, ["name"] = "default:steelblock"}, {["x"] = 6, ["y"] = 4, ["param1"] = 15, ["z"] = 2, ["name"] = "wool:black"}, {["x"] = 6, ["y"] = 4, ["param1"] = 15, ["z"] = 3, ["name"] = "wool:black"}, {["x"] = 6, ["y"] = 4, ["param1"] = 15, ["z"] = 4, ["name"] = "wool:black"}, {["x"] = 6, ["y"] = 4, ["param1"] = 15, ["z"] = 5, ["name"] = "wool:black"}, {["x"] = 6, ["y"] = 4, ["param1"] = 15, ["z"] = 6, ["name"] = "wool:black"}, {["x"] = 6, ["y"] = 4, ["param1"] = 15, ["z"] = 7, ["name"] = "wool:black"}, {["x"] = 6, ["y"] = 4, ["param1"] = 15, ["z"] = 8, ["name"] = "wool:black"}, {["x"] = 6, ["y"] = 4, ["param1"] = 15, ["z"] = 9, ["name"] = "wool:black"}, {["x"] = 6, ["y"] = 4, ["param1"] = 15, ["z"] = 10, ["name"] = "wool:black"}, {["x"] = 6, ["y"] = 4, ["param1"] = 15, ["z"] = 11, ["name"] = "wool:black"}, {["x"] = 6, ["y"] = 4, ["param1"] = 15, ["z"] = 12, ["name"] = "wool:black"}, {["x"] = 6, ["y"] = 4, ["param1"] = 15, ["z"] = 13, ["name"] = "wool:black"}, {["x"] = 6, ["y"] = 4, ["param1"] = 15, ["z"] = 14, ["name"] = "default:steelblock"}, {["x"] = 6, ["y"] = 5, ["param1"] = 15, ["z"] = 1, ["name"] = "default:steelblock"}, {["x"] = 6, ["y"] = 5, ["param1"] = 15, ["z"] = 2, ["name"] = "wool:black"}, {["x"] = 6, ["y"] = 5, ["param1"] = 15, ["z"] = 3, ["name"] = "wool:black"}, {["x"] = 6, ["y"] = 5, ["param1"] = 15, ["z"] = 4, ["name"] = "wool:black"}, {["x"] = 6, ["y"] = 5, ["param1"] = 15, ["z"] = 5, ["name"] = "wool:black"}, {["x"] = 6, ["y"] = 5, ["param1"] = 15, ["z"] = 6, ["name"] = "wool:black"}, {["x"] = 6, ["y"] = 5, ["param1"] = 15, ["z"] = 7, ["name"] = "wool:black"}, {["x"] = 6, ["y"] = 5, ["param1"] = 15, ["z"] = 8, ["name"] = "wool:black"}, {["x"] = 6, ["y"] = 5, ["param1"] = 15, ["z"] = 9, ["name"] = "wool:black"}, {["x"] = 6, ["y"] = 5, ["param1"] = 15, ["z"] = 10, ["name"] = "wool:black"}, {["x"] = 6, ["y"] = 5, ["param1"] = 15, ["z"] = 11, ["name"] = "wool:black"}, {["x"] = 6, ["y"] = 5, ["param1"] = 15, ["z"] = 12, ["name"] = "wool:black"}, {["x"] = 6, ["y"] = 5, ["param1"] = 15, ["z"] = 13, ["name"] = "wool:black"}, {["x"] = 6, ["y"] = 5, ["param1"] = 15, ["z"] = 14, ["name"] = "default:steelblock"}, {["x"] = 6, ["y"] = 6, ["param1"] = 15, ["z"] = 1, ["name"] = "default:steelblock"}, {["x"] = 6, ["y"] = 6, ["param1"] = 15, ["z"] = 2, ["name"] = "wool:black"}, {["x"] = 6, ["y"] = 6, ["param1"] = 15, ["z"] = 3, ["name"] = "wool:black"}, {["x"] = 6, ["y"] = 6, ["param1"] = 15, ["z"] = 4, ["name"] = "wool:black"}, {["x"] = 6, ["y"] = 6, ["param1"] = 15, ["z"] = 5, ["name"] = "wool:black"}, {["x"] = 6, ["y"] = 6, ["param1"] = 15, ["z"] = 6, ["name"] = "wool:black"}, {["x"] = 6, ["y"] = 6, ["param1"] = 15, ["z"] = 7, ["name"] = "wool:black"}, {["x"] = 6, ["y"] = 6, ["param1"] = 15, ["z"] = 8, ["name"] = "wool:black"}, {["x"] = 6, ["y"] = 6, ["param1"] = 15, ["z"] = 9, ["name"] = "wool:black"}, {["x"] = 6, ["y"] = 6, ["param1"] = 15, ["z"] = 10, ["name"] = "wool:black"}, {["x"] = 6, ["y"] = 6, ["param1"] = 15, ["z"] = 11, ["name"] = "wool:black"}, {["x"] = 6, ["y"] = 6, ["param1"] = 15, ["z"] = 12, ["name"] = "wool:black"}, {["x"] = 6, ["y"] = 6, ["param1"] = 15, ["z"] = 13, ["name"] = "wool:black"}, {["x"] = 6, ["y"] = 6, ["param1"] = 15, ["z"] = 14, ["name"] = "default:steelblock"}, {["x"] = 6, ["y"] = 7, ["param1"] = 15, ["z"] = 1, ["name"] = "default:steelblock"}, {["x"] = 6, ["y"] = 7, ["param1"] = 15, ["z"] = 2, ["name"] = "wool:black"}, {["x"] = 6, ["y"] = 7, ["param1"] = 15, ["z"] = 3, ["name"] = "wool:black"}, {["x"] = 6, ["y"] = 7, ["param1"] = 15, ["z"] = 4, ["name"] = "wool:black"}, {["x"] = 6, ["y"] = 7, ["param1"] = 15, ["z"] = 5, ["name"] = "wool:black"}, {["x"] = 6, ["y"] = 7, ["param1"] = 15, ["z"] = 6, ["name"] = "wool:black"}, {["x"] = 6, ["y"] = 7, ["param1"] = 15, ["z"] = 7, ["name"] = "wool:black"}, {["x"] = 6, ["y"] = 7, ["param1"] = 15, ["z"] = 8, ["name"] = "wool:black"}, {["x"] = 6, ["y"] = 7, ["param1"] = 15, ["z"] = 9, ["name"] = "wool:black"}, {["x"] = 6, ["y"] = 7, ["param1"] = 15, ["z"] = 10, ["name"] = "wool:black"}, {["x"] = 6, ["y"] = 7, ["param1"] = 15, ["z"] = 11, ["name"] = "wool:black"}, {["x"] = 6, ["y"] = 7, ["param1"] = 15, ["z"] = 12, ["name"] = "wool:black"}, {["x"] = 6, ["y"] = 7, ["param1"] = 15, ["z"] = 13, ["name"] = "wool:black"}, {["x"] = 6, ["y"] = 7, ["param1"] = 15, ["z"] = 14, ["name"] = "default:steelblock"}, {["x"] = 6, ["y"] = 8, ["param1"] = 15, ["z"] = 1, ["name"] = "default:steelblock"}, {["x"] = 6, ["y"] = 8, ["param1"] = 15, ["z"] = 2, ["name"] = "wool:black"}, {["x"] = 6, ["y"] = 8, ["param1"] = 15, ["z"] = 3, ["name"] = "wool:black"}, {["x"] = 6, ["y"] = 8, ["param1"] = 15, ["z"] = 4, ["name"] = "wool:black"}, {["x"] = 6, ["y"] = 8, ["param1"] = 15, ["z"] = 5, ["name"] = "wool:black"}, {["x"] = 6, ["y"] = 8, ["param1"] = 15, ["z"] = 6, ["name"] = "wool:black"}, {["x"] = 6, ["y"] = 8, ["param1"] = 15, ["z"] = 7, ["name"] = "wool:black"}, {["x"] = 6, ["y"] = 8, ["param1"] = 15, ["z"] = 8, ["name"] = "wool:black"}, {["x"] = 6, ["y"] = 8, ["param1"] = 15, ["z"] = 9, ["name"] = "wool:black"}, {["x"] = 6, ["y"] = 8, ["param1"] = 15, ["z"] = 10, ["name"] = "wool:black"}, {["x"] = 6, ["y"] = 8, ["param1"] = 15, ["z"] = 11, ["name"] = "wool:black"}, {["x"] = 6, ["y"] = 8, ["param1"] = 15, ["z"] = 12, ["name"] = "wool:black"}, {["x"] = 6, ["y"] = 8, ["param1"] = 15, ["z"] = 13, ["name"] = "wool:black"}, {["x"] = 6, ["y"] = 8, ["param1"] = 15, ["z"] = 14, ["name"] = "default:steelblock"}, {["x"] = 6, ["y"] = 9, ["param1"] = 15, ["z"] = 1, ["name"] = "default:steelblock"}, {["x"] = 6, ["y"] = 9, ["param1"] = 15, ["z"] = 2, ["name"] = "wool:black"}, {["x"] = 6, ["y"] = 9, ["param1"] = 15, ["z"] = 3, ["name"] = "wool:black"}, {["x"] = 6, ["y"] = 9, ["param1"] = 15, ["z"] = 4, ["name"] = "wool:black"}, {["x"] = 6, ["y"] = 9, ["param1"] = 15, ["z"] = 5, ["name"] = "wool:black"}, {["x"] = 6, ["y"] = 9, ["param1"] = 15, ["z"] = 6, ["name"] = "wool:black"}, {["x"] = 6, ["y"] = 9, ["param1"] = 15, ["z"] = 7, ["name"] = "wool:black"}, {["x"] = 6, ["y"] = 9, ["param1"] = 15, ["z"] = 8, ["name"] = "wool:black"}, {["x"] = 6, ["y"] = 9, ["param1"] = 15, ["z"] = 9, ["name"] = "wool:black"}, {["x"] = 6, ["y"] = 9, ["param1"] = 15, ["z"] = 10, ["name"] = "wool:black"}, {["x"] = 6, ["y"] = 9, ["param1"] = 15, ["z"] = 11, ["name"] = "wool:black"}, {["x"] = 6, ["y"] = 9, ["param1"] = 15, ["z"] = 12, ["name"] = "wool:black"}, {["x"] = 6, ["y"] = 9, ["param1"] = 15, ["z"] = 13, ["name"] = "wool:black"}, {["x"] = 6, ["y"] = 9, ["param1"] = 15, ["z"] = 14, ["name"] = "default:steelblock"}, {["x"] = 6, ["y"] = 10, ["param1"] = 15, ["z"] = 1, ["name"] = "default:steelblock"}, {["x"] = 6, ["y"] = 10, ["param1"] = 15, ["z"] = 2, ["name"] = "wool:black"}, {["x"] = 6, ["y"] = 10, ["param1"] = 15, ["z"] = 3, ["name"] = "wool:black"}, {["x"] = 6, ["y"] = 10, ["param1"] = 15, ["z"] = 4, ["name"] = "wool:black"}, {["x"] = 6, ["y"] = 10, ["param1"] = 15, ["z"] = 5, ["name"] = "wool:black"}, {["x"] = 6, ["y"] = 10, ["param1"] = 15, ["z"] = 6, ["name"] = "wool:black"}, {["x"] = 6, ["y"] = 10, ["param1"] = 15, ["z"] = 7, ["name"] = "wool:black"}, {["x"] = 6, ["y"] = 10, ["param1"] = 15, ["z"] = 8, ["name"] = "wool:black"}, {["x"] = 6, ["y"] = 10, ["param1"] = 15, ["z"] = 9, ["name"] = "wool:black"}, {["x"] = 6, ["y"] = 10, ["param1"] = 15, ["z"] = 10, ["name"] = "wool:black"}, {["x"] = 6, ["y"] = 10, ["param1"] = 15, ["z"] = 11, ["name"] = "wool:black"}, {["x"] = 6, ["y"] = 10, ["param1"] = 15, ["z"] = 12, ["name"] = "wool:black"}, {["x"] = 6, ["y"] = 10, ["param1"] = 15, ["z"] = 13, ["name"] = "wool:black"}, {["x"] = 6, ["y"] = 10, ["param1"] = 15, ["z"] = 14, ["name"] = "default:steelblock"}, {["x"] = 6, ["y"] = 11, ["param1"] = 15, ["z"] = 1, ["name"] = "default:steelblock"}, {["x"] = 6, ["y"] = 11, ["param1"] = 15, ["z"] = 2, ["name"] = "wool:black"}, {["x"] = 6, ["y"] = 11, ["param1"] = 15, ["z"] = 3, ["name"] = "wool:black"}, {["x"] = 6, ["y"] = 11, ["param1"] = 15, ["z"] = 4, ["name"] = "wool:black"}, {["x"] = 6, ["y"] = 11, ["param1"] = 15, ["z"] = 5, ["name"] = "wool:black"}, {["x"] = 6, ["y"] = 11, ["param1"] = 15, ["z"] = 6, ["name"] = "wool:black"}, {["x"] = 6, ["y"] = 11, ["param1"] = 15, ["z"] = 7, ["name"] = "wool:black"}, {["x"] = 6, ["y"] = 11, ["param1"] = 15, ["z"] = 8, ["name"] = "wool:black"}, {["x"] = 6, ["y"] = 11, ["param1"] = 15, ["z"] = 9, ["name"] = "wool:black"}, {["x"] = 6, ["y"] = 11, ["param1"] = 15, ["z"] = 10, ["name"] = "wool:black"}, {["x"] = 6, ["y"] = 11, ["param1"] = 15, ["z"] = 11, ["name"] = "wool:black"}, {["x"] = 6, ["y"] = 11, ["param1"] = 15, ["z"] = 12, ["name"] = "wool:black"}, {["x"] = 6, ["y"] = 11, ["param1"] = 15, ["z"] = 13, ["name"] = "wool:black"}, {["x"] = 6, ["y"] = 11, ["param1"] = 15, ["z"] = 14, ["name"] = "default:steelblock"}, {["x"] = 6, ["y"] = 12, ["param1"] = 15, ["z"] = 2, ["name"] = "wool:black"}, {["x"] = 6, ["y"] = 12, ["param1"] = 15, ["z"] = 3, ["name"] = "wool:black"}, {["x"] = 6, ["y"] = 12, ["param1"] = 15, ["z"] = 4, ["name"] = "wool:black"}, {["x"] = 6, ["y"] = 12, ["param1"] = 15, ["z"] = 5, ["name"] = "wool:black"}, {["x"] = 6, ["y"] = 12, ["param1"] = 15, ["z"] = 6, ["name"] = "wool:black"}, {["x"] = 6, ["y"] = 12, ["param1"] = 15, ["z"] = 7, ["name"] = "wool:black"}, {["x"] = 6, ["y"] = 12, ["param1"] = 15, ["z"] = 8, ["name"] = "wool:black"}, {["x"] = 6, ["y"] = 12, ["param1"] = 15, ["z"] = 9, ["name"] = "wool:black"}, {["x"] = 6, ["y"] = 12, ["param1"] = 15, ["z"] = 10, ["name"] = "wool:black"}, {["x"] = 6, ["y"] = 12, ["param1"] = 15, ["z"] = 11, ["name"] = "wool:black"}, {["x"] = 6, ["y"] = 12, ["param1"] = 15, ["z"] = 12, ["name"] = "wool:black"}, {["x"] = 6, ["y"] = 12, ["param1"] = 15, ["z"] = 13, ["name"] = "wool:black"}, {["x"] = 6, ["y"] = 13, ["param1"] = 15, ["z"] = 2, ["name"] = "wool:black"}, {["x"] = 6, ["y"] = 13, ["param1"] = 15, ["z"] = 3, ["name"] = "wool:black"}, {["x"] = 6, ["y"] = 13, ["param1"] = 15, ["z"] = 4, ["name"] = "wool:black"}, {["x"] = 6, ["y"] = 13, ["param1"] = 15, ["z"] = 5, ["name"] = "wool:black"}, {["x"] = 6, ["y"] = 13, ["param1"] = 15, ["z"] = 6, ["name"] = "wool:black"}, {["x"] = 6, ["y"] = 13, ["param1"] = 15, ["z"] = 7, ["name"] = "wool:black"}, {["x"] = 6, ["y"] = 13, ["param1"] = 15, ["z"] = 8, ["name"] = "wool:black"}, {["x"] = 6, ["y"] = 13, ["param1"] = 15, ["z"] = 9, ["name"] = "wool:black"}, {["x"] = 6, ["y"] = 13, ["param1"] = 15, ["z"] = 10, ["name"] = "wool:black"}, {["x"] = 6, ["y"] = 13, ["param1"] = 15, ["z"] = 11, ["name"] = "wool:black"}, {["x"] = 6, ["y"] = 13, ["param1"] = 15, ["z"] = 12, ["name"] = "wool:black"}, {["x"] = 6, ["y"] = 13, ["param1"] = 15, ["z"] = 13, ["name"] = "wool:black"}, {["x"] = 6, ["y"] = 14, ["z"] = 1, ["name"] = "wool:black"}, {["x"] = 6, ["y"] = 14, ["param1"] = 15, ["z"] = 2, ["name"] = "wool:black"}, {["x"] = 6, ["y"] = 14, ["param1"] = 15, ["z"] = 3, ["name"] = "wool:black"}, {["x"] = 6, ["y"] = 14, ["param1"] = 15, ["z"] = 4, ["name"] = "wool:black"}, {["x"] = 6, ["y"] = 14, ["param1"] = 15, ["z"] = 5, ["name"] = "wool:black"}, {["x"] = 6, ["y"] = 14, ["param1"] = 15, ["z"] = 6, ["name"] = "wool:black"}, {["x"] = 6, ["y"] = 14, ["param1"] = 15, ["z"] = 7, ["name"] = "wool:black"}, {["x"] = 6, ["y"] = 14, ["param1"] = 15, ["z"] = 8, ["name"] = "wool:black"}, {["x"] = 6, ["y"] = 14, ["param1"] = 15, ["z"] = 9, ["name"] = "wool:black"}, {["x"] = 6, ["y"] = 14, ["param1"] = 15, ["z"] = 10, ["name"] = "wool:black"}, {["x"] = 6, ["y"] = 14, ["param1"] = 15, ["z"] = 11, ["name"] = "wool:black"}, {["x"] = 6, ["y"] = 14, ["param1"] = 15, ["z"] = 12, ["name"] = "wool:black"}, {["x"] = 6, ["y"] = 14, ["param1"] = 15, ["z"] = 13, ["name"] = "wool:black"}, {["x"] = 6, ["y"] = 14, ["z"] = 14, ["name"] = "wool:black"}, {["x"] = 6, ["y"] = 15, ["z"] = 1, ["name"] = "wool:black"}, {["x"] = 6, ["y"] = 15, ["param1"] = 14, ["z"] = 2, ["name"] = "wool:black"}, {["x"] = 6, ["y"] = 15, ["param1"] = 14, ["z"] = 3, ["name"] = "wool:black"}, {["x"] = 6, ["y"] = 15, ["param1"] = 14, ["z"] = 4, ["name"] = "wool:black"}, {["x"] = 6, ["y"] = 15, ["param1"] = 14, ["z"] = 5, ["name"] = "wool:black"}, {["x"] = 6, ["y"] = 15, ["param1"] = 14, ["z"] = 6, ["name"] = "wool:black"}, {["x"] = 6, ["y"] = 15, ["param1"] = 14, ["z"] = 7, ["name"] = "wool:black"}, {["x"] = 6, ["y"] = 15, ["param1"] = 14, ["z"] = 8, ["name"] = "wool:black"}, {["x"] = 6, ["y"] = 15, ["param1"] = 14, ["z"] = 9, ["name"] = "wool:black"}, {["x"] = 6, ["y"] = 15, ["param1"] = 14, ["z"] = 10, ["name"] = "wool:black"}, {["x"] = 6, ["y"] = 15, ["param1"] = 14, ["z"] = 11, ["name"] = "wool:black"}, {["x"] = 6, ["y"] = 15, ["param1"] = 14, ["z"] = 12, ["name"] = "wool:black"},